Workbook

Sheet Supuestos y Consideraciones
B2: Supuestos y consideraciones
B4: Posibles variables que definen a un escenario | K4: Parámetros relevantes del Sistema Eléctrico en Chile
B5: 1) Extensión del despliegue (% de consumidores). | K5: Parámetro | Q5: Unidad | R5: Valor | S5: Comentario
B6: 2) Tiempo de plazo para el despliegue. | K6: Variación proyectada del consumo de energía | Q6: %
B7: 3) Número de funcionalidades del Sistema de Medición Inteligente. | K7: Variación proyectada de los precios de la energía | Q7: %
B8: 4) Densidad de clientes en el despliegue (Urbano vs Rural). | K8: Transferencia de carga de punta | Q8: %
K9: Pérdidas eléctricas en niveles de transmisión y distribución | Q9: %
K10: Minutos no suministrados estimados | Q10: Cantidad
B11: Escenario 0 (Caso Base, sin despliegue): | K11: Valor de Energía No Suministrada; valor del suministro | Q11: $/kWh
B12: Variables | H12: Valor | K12: Tasa de descuento | Q12: %
B13: 1) Extensión del despliegue (% de consumidores). | H13: 0 | K13: Costos de hardware (p. ej, medidor inteligente, módem GPRS/PLC, etc.) | Q13: $
B14: 2) Tiempo de plazo para el despliegue. | H14: 2030 | K14: Número de medidores inteligentes a instalar | Q14: Cantidad
B15: 3) Número de funcionalidades del Sistema de Medición Inteligente. | H15: 0 | K15: Costos de instalación del sistema de medición inteligente | Q15: $
K16: Vida útil del sistema de medición inteligente | Q16: Años
K17: Costos de lectura de medidores | Q17: $/año
B18: Escenario 1: | K18: Tasa de éxito de telecomunicación | Q18: %
B19: Variables | H19: Valor | K19: Tasa de inflación | Q19: %
B20: 1) Extensión del despliegue (% de consumidores). | H20: 0.8 | K20: Reducción de costos asociada a la madurez tecnológica | Q20: %
B21: 2) Tiempo de plazo para el despliegue. | H21: 2030 | K21: Calendario de implementación | Q21: Cantidad/año
B22: 3) Número de funcionalidades del Sistema de Medición Inteligente. | H22: 10 | K22: Porcentaje de medidores ubicados en zonas rurales vs urbanas | Q22: %
K23: Costos de carbono | Q23: $/ton

Sheet CB_SMMC_Mixto
A1: Concepto | B1: Periodo 0 | C1: Periodo 1 | D1: Periodo 2 | E1: Periodo 3 | F1: Periodo 4 | G1: Periodo 5 | H1: Periodo 6 | I1: Periodo 7 | J1: Periodo 8 | K1: Periodo 9 | L1: Periodo 10 | M1: Periodo 11 | N1: Periodo 12 | O1: Periodo 13 | P1: Periodo 14 | Q1: Periodo 15
A2: Energía facturada anual [MWh/año] | B2: 34765766 | C2: 35815692 | D2: 36897326 | E2: 38011625 | F2: 39159576 | G2: 40342196 | H2: 41560530 | I2: 42815658 | J2: 44108691 | K2: 45440773 | L2: 46813085 | M2: 48226840 | N2: 49683290 | O2: 51183726 | P2: 52729474 | Q2: 54321904
A3: Cantidad UM 1F | B3: 22317 | C3: 58 | D3: 7913832 | E3: 117376 | F3: 119200 | G3: 121056 | H3: 122935 | I3: 124861 | J3: 126789 | K3: 128764 | L3: 130761 | M3: 132814 | N3: 134885 | O3: 136990 | P3: 139136 | Q3: 141300
A4: Cantidad UM 3F Directa | B4: 0 | C4: 0 | D4: 57595 | E4: 528 | F4: 539 | G4: 549 | H4: 558 | I4: 564 | J4: 570 | K4: 576 | L4: 589 | M4: 594 | N4: 602 | O4: 612 | P4: 621 | Q4: 632
A5: Cantidad UM 3F Indirecta | B5: 216250 | C5: 426 | D5: 426 | E5: 5 | F5: 5 | G5: 5 | H5: 5 | I5: 5 | J5: 5 | K5: 5 | L5: 5 | M5: 5 | N5: 5 | O5: 5 | P5: 5 | Q5: 5
A6: Cantidad DCU | B6: 0 | C6: 0 | D6: 56029 | E6: 0 | F6: 0 | G6: 0 | H6: 0 | I6: 0 | J6: 0 | K6: 0 | L6: 0 | M6: 0 | N6: 0 | O6: 0 | P6: 0 | Q6: 0
A7: Inversión UM 1F [USD/equipo] | B7: 178.26664 | C7: 171.9468 | D7: 151.66546 | E7: 152.21105 | F7: 152.21368 | G7: 152.22118 | H7: 152.2329 | I7: 152.24041 | J7: 152.24377 | K7: 152.25391 | L7: 152.25818 | M7: 152.26724 | N7: 152.27683 | O7: 152.28357 | P7: 152.29026 | Q7: 152.29636
A8: Inversión UM 3F Directa [USD/equipo] | B8: 0 | C8: 0 | D8: 354.21361 | E8: 344.69062 | F8: 344.75088 | G8: 344.82929 | H8: 344.9253 | I8: 344.91391 | J8: 344.9029 | K8: 344.86492 | L8: 344.71965 | M8: 344.78239 | N8: 344.73573 | O8: 344.75552 | P8: 344.89291 | Q8: 344.84227
A9: Inversión UM 3F Indirecta [USD/equipo] | B9: 785.89288 | C9: 756.97637 | D9: 760.16099 | E9: 779.91498 | F9: 779.91498 | G9: 779.91498 | H9: 779.91498 | I9: 779.91498 | J9: 779.91498 | K9: 779.91498 | L9: 779.91498 | M9: 779.91498 | N9: 779.91498 | O9: 779.91498 | P9: 779.91498 | Q9: 779.91498
A10: Inversión DCU [USD/equipo] | B10: 0 | C10: 0 | D10: 815.57704 | E10: 0 | F10: 0 | G10: 0 | H10: 0 | I10: 0 | J10: 0 | K10: 0 | L10: 0 | M10: 0 | N10: 0 | O10: 0 | P10: 0 | Q10: 0
A11: Inversión SGO [USD] | B11: 4377943 | C11: 8881.884 | D11: 1.4629147e+08 | E11: 2163748.1 | F11: 2197422.1 | G11: 2231665.1 | H11: 2266311.8 | I11: 2301765.9 | J11: 2337256.8 | K11: 2373610.1 | L11: 2410495.6 | M11: 2448262 | N11: 2486413.7 | O11: 2525226.1 | P11: 2564772.5 | Q11: 2604685.9
A12: Inversión MDMS [USD] | B12: 328971.34 | C12: 667.41053 | D12: 10992766 | E12: 162590.31 | F12: 165120.67 | G12: 167693.79 | H12: 170297.24 | I12: 172961.37 | J12: 175628.25 | K12: 178359.95 | L12: 181131.63 | M12: 183969.51 | N12: 186836.34 | O12: 189752.81 | P12: 192724.44 | Q12: 195723.65
A13: Operación Comunicaciones [USD/año] | B13: 8355415.3 | C13: 8372366.6 | D13: 8372366.6 | E13: 8372366.6 | F13: 8372366.6 | G13: 8372366.6 | H13: 8372366.6 | I13: 8372366.6 | J13: 8372366.6 | K13: 8372366.6 | L13: 8372366.6 | M13: 8372366.6 | N13: 8372366.6 | O13: 8372366.6 | P13: 8372366.6 | Q13: 8372366.6
... A26: Ahorro por inversión evitada [USD/año] | B26: 14977606 | C26: 14988568 | D26: 14999800 | E26: 15164611 | F26: 15200012 | G26: 15223020 | H26: 15239526 | I26: 15255590 | J26: 15381185 | K26: 15413471 | L26: 15438892 | M26: 15464348 | N26: 15494515 | O26: 15539869 | P26: 15585356 | Q26: 15630977

Sheet Flujo de Caja SMI Mixto 10 años
B2: Escenario de implementación | G2: Supuestos y Consideraciones
B4: Densidad de clientes | D4: Tecnología | G4: Tasa de descuento | J4: 0.06 | K4: % | R4: Dólar | S4: 959.36 | T4: $/USD | U4: 45946
B5: Alta | D5: G3-PLC | G5: Vida útil del proyecto | J5: 15 | K5: años | R5: UF | S5: 39521.26 | T5: $/UF | U5: 45946
B6: Media | D6: G3-PLC | G6: Meta de despligue | J6: 12 | K6: años
B7: Baja | D7: RF-Mesh | G7: Objetivo de despligue UM 1F | J7: =SUM(H17:Q17)/J6 -> 753199 | K7: UM/año | L7: ="Razonable para chile en torno a 1M y 1,5M por año." -> Razonable para chile en torno a 1M y 1,5M por año.
B8: Muy Baja | D8: LoRa | G8: Objetivo de despligue UM 3F Directa | J8: =SUM(H18:Q18)/J6 -> 5221.8333 | K8: UM/año | L8: ="Razonable para chile en torno a 1M y 1,5M por año." -> Razonable para chile en torno a 1M y 1,5M por año.
B9: Extremadamente Baja | D9: LoRa | G9: Objetivo de despligue UM 3F Indirecta | J9: =SUM(F19:O19)/J6 -> 18094.75 | K9: UM/año | L9: ="Razonable para chile en torno a 1M y 1,5M por año." -> Razonable para chile en torno a 1M y 1,5M por año. | R9: Total a 2027: | S9: =SUM(F17:H19) -> 8210904
B12: Despligue SMI Chile | E12: Periodo | F12: -2 | G12: 0 | H12: 1 | I12: 2 | J12: 3 | K12: 4 | L12: 5 | M12: 6 | N12: 7 | O12: 8 | P12: 9 | Q12: 10 | R12: 11 | S12: 12 | T12: 13 | U12: 14
E13: Año | F13: 2025 | G13: 2026 | H13: 2027 | I13: 2028 | J13: 2029 | K13: 2030 | L13: 2031 | M13: 2032 | N13: 2033 | O13: 2034 | P13: 2035 | Q13: 2036 | R13: 2037 | S13: 2038 | T13: 2039 | U13: 2040
B15: Datos de despliegue | C15: Energía Facturada anual [GWh] | F15: ='CB_SMMC_Mixto'!B2/1000 -> 34765.766 | G15: ='CB_SMMC_Mixto'!C2/1000 -> 35815.692 | H15: ='CB_SMMC_Mixto'!D2/1000 -> 36897.326 | I15: ='CB_SMMC_Mixto'!E2/1000 -> 38011.625 | J15: ='CB_SMMC_Mixto'!F2/1000 -> 39159.576 | K15: ='CB_SMMC_Mixto'!G2/1000 -> 40342.196 | L15: ='CB_SMMC_Mixto'!H2/1000 -> 41560.53 | M15: ='CB_SMMC_Mixto'!I2/1000 -> 42815.658 | ... U15: ='CB_SMMC_Mixto'!Q2/1000 -> 54321.904
C17: UM 1F [N° Equipos] | F17: ='CB_SMMC_Mixto'!B3 -> 22317 | G17: ='CB_SMMC_Mixto'!C3 -> 58 | H17: ='CB_SMMC_Mixto'!D3 -> 7913832 | I17: ='CB_SMMC_Mixto'!E3 -> 117376 | J17: ='CB_SMMC_Mixto'!F3 -> 119200 | K17: ='CB_SMMC_Mixto'!G3 -> 121056 | L17: ='CB_SMMC_Mixto'!H3 -> 122935 | M17: ='CB_SMMC_Mixto'!I3 -> 124861 | ... U17: ='CB_SMMC_Mixto'!Q3 -> 141300 | V17: =SUM(H17:U17)+F17 -> 9613016
C18: UM 3F Directa [N° Equipos] | F18: ='CB_SMMC_Mixto'!B4 -> 0 | G18: ='CB_SMMC_Mixto'!C4 -> 0 | H18: ='CB_SMMC_Mixto'!D4 -> 57595 | I18: ='CB_SMMC_Mixto'!E4 -> 528 | J18: ='CB_SMMC_Mixto'!F4 -> 539 | K18: ='CB_SMMC_Mixto'!G4 -> 549 | L18: ='CB_SMMC_Mixto'!H4 -> 558 | M18: ='CB_SMMC_Mixto'!I4 -> 564 | ... U18: ='CB_SMMC_Mixto'!Q4 -> 632
C19: UM 3F Indirecta [N° Equipos] | F19: ='CB_SMMC_Mixto'!B5 -> 216250 | G19: ='CB_SMMC_Mixto'!C5 -> 426 | H19: ='CB_SMMC_Mixto'!D5 -> 426 | I19: ='CB_SMMC_Mixto'!E5 -> 5 | J19: ='CB_SMMC_Mixto'!F5 -> 5 | K19: ='CB_SMMC_Mixto'!G5 -> 5 | L19: ='CB_SMMC_Mixto'!H5 -> 5 | M19: ='CB_SMMC_Mixto'!I5 -> 5 | ... U19: ='CB_SMMC_Mixto'!Q5 -> 5
B21: Despliegue | C21: UM 1F instalados | F21: =F17 -> 22317 | G21: =G17 -> 58 | H21: =IF(H$12<=$J$6,$J7,H17) -> 753199 | I21: =IF(I$12<=$J$6,$J7,I17) -> 753199 | J21: =IF(J$12<=$J$6,$J7,J17) -> 753199 | K21: =IF(K$12<=$J$6,$J7,K17) -> 753199 | L21: =IF(L$12<=$J$6,$J7,L17) -> 753199 | M21: =IF(M$12<=$J$6,$J7,M17) -> 753199 | N21: =IF(N$12<=$J$6,$J7,N17) -> 753199 | O21: =IF(O$12<=$J$6,$J7,O17) -> 753199 | ... U21: =IF(U$12<=$J$6,$J7,U17) -> 141300 | V21: =SUM(H21:P21) -> 6778791
C22: UM 3F Directa instalados | F22: =F18 -> 0 | G22: 0 | H22: =IF(H$12<=$J$6,$J8,H18) -> 5221.8333 | I22: =IF(I$12<=$J$6,$J8,I18) -> 5221.8333 | J22: =IF(J$12<=$J$6,$J8,J18) -> 5221.8333 | K22: =IF(K$12<=$J$6,$J8,K18) -> 5221.8333 | L22: =IF(L$12<=$J$6,$J8,L18) -> 5221.8333 | M22: =IF(M$12<=$J$6,$J8,M18) -> 5221.8333 | N22: =IF(N$12<=$J$6,$J8,N18) -> 5221.8333 | O22: =IF(O$12<=$J$6,$J8,O18) -> 5221.8333 | ... U22: =IF(U$12<=$J$6,$J8,U18) -> 632
C23: UM 3F Indirecta instalados | F23: =$J$9 -> 18094.75 | G23: =$J$9 -> 18094.75 | H23: =$J$9 -> 18094.75 | I23: =$J$9 -> 18094.75 | J23: =$J$9 -> 18094.75 | K23: =$J$9 -> 18094.75 | L23: =$J$9 -> 18094.75 | M23: =$J$9 -> 18094.75 | ... O23: =$J$9 -> 18094.75 | P23: =P19 -> 5 | Q23: =Q19 -> 5 | R23: =IF(R$12<=$J$6,$J9,R19) -> 18094.75 | S23: =IF(S$12<=$J$6,$J9,S19) -> 18094.75 | T23: =IF(T$12<=$J$6,$J9,T19) -> 5 | U23: =IF(U$12<=$J$6,$J9,U19) -> 5
C24: UM faltantes por instalar | F24: =SUM(F17:F19)-SUM(F21:F23) -> 198155.25 | G24: =SUM(F24,G17:G19)-SUM(G21:G23) -> 180486.5 | H24: =SUM(G24,H17:H19)-SUM(H21:H23) -> 7375823.9 | I24: =SUM(H24,I17:I19)-SUM(I21:I23) -> 6717217.3 | J24: =SUM(I24,J17:J19)-SUM(J21:J23) -> 6060445.8 | K24: =SUM(J24,K17:K19)-SUM(K21:K23) -> 5405540.2 | L24: =SUM(K24,L17:L19)-SUM(L21:L23) -> 4752522.6 | M24: =SUM(L24,M17:M19)-SUM(M21:M23) -> 4101437 | N24: =SUM(M24,N17:N19)-SUM(N21:N23) -> 3452285.4 | ... U24: =SUM(T24,U17:U19)-SUM(U21:U23) -> 273099
C25: % de avance | F25: =IF(F$12<=$J$6,SUM($F$21:F23)/$S$9,1) -> 0.0049217175 | G25: =IF(G$12<=$J$6,SUM($F$21:G23)/$S$9,1) -> 0.0071325277 | H25: =IF(H$12<=$J$6,SUM($F$21:H23)/SUM($F$17:H19),1) -> 0.10170379 | I25: =IF(I$12<=$J$6,SUM($F$21:I23)/SUM($F$17:I19),1) -> 0.19349644 | J25: =IF(J$12<=$J$6,SUM($F$21:J23)/SUM($F$17:J19),1) -> 0.28266499 | K25: =IF(K$12<=$J$6,SUM($F$21:K23)/SUM($F$17:K19),1) -> 0.36926081 | L25: =IF(L$12<=$J$6,SUM($F$21:L23)/SUM($F$17:L19),1) -> 0.45333498 | M25: =IF(M$12<=$J$6,SUM($F$21:M23)/SUM($F$17:M19),1) -> 0.53493675 | N25: =IF(N$12<=$J$6,SUM($F$21:N23)/SUM($F$17:N19),1) -> 0.61411711 | O25: =IF(O$12<=$J$6,SUM($F$21:O23)/SUM($F$17:O19),1) -> 0.69092382 | ... U25: =IF(U$12<=$J$6,SUM($F$21:U23)/SUM($F$17:U19),1) -> 1
B27: Flujo de caja [MUSD] | E27: Periodo | F27: -2 | G27: -1 | H27: 0 | I27: 1 | J27: 2 | K27: 3 | L27: 4 | M27: 5 | N27: 6 | O27: 7 | P27: 8 | Q27: 9 | R27: 10 | S27: 11 | T27: 12 | U27: 13
E28: Año | F28: 2025 | G28: 2026 | H28: 2027 | I28: 2028 | J28: 2029 | K28: 2030 | L28: 2031 | M28: 2032 | N28: 2033 | O28: 2034 | P28: 2035 | Q28: 2036 | R28: 2037 | S28: 2038 | T28: 2039 | U28: 2040 | W28: VAN [MUSD] | X28: AVAN [MUSD] | Y28: VAN [USD/# Clientes] | Z28: Participación %
B30: VI [MUSD] | C30: UM 1F | F30: =((-'CB_SMMC_Mixto'!B7)*F21)/1000000 -> -3.9783767 | G30: =((-'CB_SMMC_Mixto'!C7)*G21)/1000000 -> -0.0099729147 | H30: =((-'CB_SMMC_Mixto'!D7)*H21)/1000000 -> -114.23427 | I30: =((-'CB_SMMC_Mixto'!E7)*I21)/1000000 -> -114.64521 | J30: =((-'CB_SMMC_Mixto'!F7)*J21)/1000000 -> -114.64719 | K30: =((-'CB_SMMC_Mixto'!G7)*K21)/1000000 -> -114.65284 | L30: =((-'CB_SMMC_Mixto'!H7)*L21)/1000000 -> -114.66167 | M30: =((-'CB_SMMC_Mixto'!I7)*M21)/1000000 -> -114.66732 | ... U30: =((-'CB_SMMC_Mixto'!Q7)*U21)/1000000 -> -21.519475 | W30: =NPV($D$68,G30:U30)+F30 -> -928.89565 | X30: =PMT($D$68,15,-W30) -> -95.641664 | Y30: =W30*1000000/7744865 -> -119.93697 | Z30: =W30/$W$36 -> 0.73040095
C31: UM 3F Directa | F31: 0 | G31: =((-'CB_SMMC_Mixto'!C8)*G22)/1000000 -> 0 | H31: =((-'CB_SMMC_Mixto'!D8)*H22)/1000000 -> -1.8496444 | I31: =((-'CB_SMMC_Mixto'!E8)*I22)/1000000 -> -1.799917 | J31: =((-'CB_SMMC_Mixto'!F8)*J22)/1000000 -> -1.8002316 | K31: =((-'CB_SMMC_Mixto'!G8)*K22)/1000000 -> -1.8006411 | L31: =((-'CB_SMMC_Mixto'!H8)*L22)/1000000 -> -1.8011424 | M31: =((-'CB_SMMC_Mixto'!I8)*M22)/1000000 -> -1.8010829 | N31: =((-'CB_SMMC_Mixto'!J8)*N22)/1000000 -> -1.8010255 | ... U31: =((-'CB_SMMC_Mixto'!Q8)*U22)/1000000 -> -0.21794031 | W31: =NPV($D$68,G31:U31)+F31 -> -14.470264 | X31: =PMT($D$68,15,-W31) -> -1.4898984 | Y31: =W31*1000000/7744865 -> -1.8683688 | Z31: =W31/$W$36 -> 0.011378129
C32: UM 3F Indirecta | F32: =((-'CB_SMMC_Mixto'!B9)*F23)/1000000 -> -14.220535 | G32: =((-'CB_SMMC_Mixto'!C9)*G23)/1000000 -> -13.697298 | H32: =((-'CB_SMMC_Mixto'!D9)*H23)/1000000 -> -13.754923 | I32: =((-'CB_SMMC_Mixto'!E9)*I23)/1000000 -> -14.112367 | J32: =((-'CB_SMMC_Mixto'!F9)*J23)/1000000 -> -14.112367 | K32: =((-'CB_SMMC_Mixto'!G9)*K23)/1000000 -> -14.112367 | L32: =((-'CB_SMMC_Mixto'!H9)*L23)/1000000 -> -14.112367 | M32: =((-'CB_SMMC_Mixto'!I9)*M23)/1000000 -> -14.112367 | ... U32: =((-'CB_SMMC_Mixto'!Q9)*U23)/1000000 -> -0.0038995749 | W32: =NPV($D$68,G32:U32)+F32 -> -123.13624 | X32: =PMT($D$68,15,-W32) -> -12.678447 | Y32: =W32*1000000/7744865 -> -15.899081 | Z32: =W32/$W$36 -> 0.096823389
C33: DCU | F33: =((-'CB_SMMC_Mixto'!B10)*'CB_SMMC_Mixto'!B6)/1000000 -> 0 | G33: =((-'CB_SMMC_Mixto'!C10)*'CB_SMMC_Mixto'!C6)/1000000 -> 0 | H33: =((-'CB_SMMC_Mixto'!D10)*'CB_SMMC_Mixto'!D6)/1000000 -> -45.695966 | I33: =((-'CB_SMMC_Mixto'!E10)*'CB_SMMC_Mixto'!E6)/1000000 -> 0 | J33: =((-'CB_SMMC_Mixto'!F10)*'CB_SMMC_Mixto'!F6)/1000000 -> 0 | K33: =((-'CB_SMMC_Mixto'!G10)*'CB_SMMC_Mixto'!G6)/1000000 -> 0 | L33: =((-'CB_SMMC_Mixto'!H10)*'CB_SMMC_Mixto'!H6)/1000000 -> 0 | M33: =((-'CB_SMMC_Mixto'!I10)*'CB_SMMC_Mixto'!I6)/1000000 -> 0 | ... U33: =((-'CB_SMMC_Mixto'!Q10)*'CB_SMMC_Mixto'!Q6)/1000000 -> 0 | W33: =NPV($D$68,G33:U33)+F33 -> -40.669247 | X33: =PMT($D$68,15,-W33) -> -4.1874181 | Y33: =W33*1000000/7744865 -> -5.2511241 | Z33: =W33/$W$36 -> 0.03197868
C34: HES | F34: =(-'CB_SMMC_Mixto'!B11)/1000000 -> -4.377943 | G34: =(-'CB_SMMC_Mixto'!C11)/1000000 -> -0.008881884 | H34: =(-'CB_SMMC_Mixto'!D11)/1000000 -> -146.29147 | I34: =(-'CB_SMMC_Mixto'!E11)/1000000 -> -2.1637481 | J34: =(-'CB_SMMC_Mixto'!F11)/1000000 -> -2.1974221 | K34: =(-'CB_SMMC_Mixto'!G11)/1000000 -> -2.2316651 | L34: =(-'CB_SMMC_Mixto'!H11)/1000000 -> -2.2663118 | M34: =(-'CB_SMMC_Mixto'!I11)/1000000 -> -2.3017659 | ... U34: =(-'CB_SMMC_Mixto'!Q11)/1000000 -> -2.6046859 | W34: =NPV($D$68,G34:U34)+F34 -> -153.08652 | X34: =PMT($D$68,15,-W34) -> -15.762211 | Y34: =W34*1000000/7744865 -> -19.766196 | Z34: =W34/$W$36 -> 0.12037363
C35: MDMS | F35: =(-'CB_SMMC_Mixto'!B12)/1000000 -> -0.32897134 | G35: =(-'CB_SMMC_Mixto'!C12)/1000000 -> -0.00066741053 | H35: =(-'CB_SMMC_Mixto'!D12)/1000000 -> -10.992766 | I35: =(-'CB_SMMC_Mixto'!E12)/1000000 -> -0.16259031 | J35: =(-'CB_SMMC_Mixto'!F12)/1000000 -> -0.16512067 | K35: =(-'CB_SMMC_Mixto'!G12)/1000000 -> -0.16769379 | L35: =(-'CB_SMMC_Mixto'!H12)/1000000 -> -0.17029724 | M35: =(-'CB_SMMC_Mixto'!I12)/1000000 -> -0.17296137 | ... U35: =(-'CB_SMMC_Mixto'!Q12)/1000000 -> -0.19572365 | W35: =NPV($D$68,G35:U35)+F35 -> -11.503365 | X35: =PMT($D$68,15,-W35) -> -1.1844183 | Y35: =W35*1000000/7744865 -> -1.4852893 | Z35: =W35/$W$36 -> 0.0090452237
C36: VI Total: | F36: =SUM(F30:F35) -> -22.905826 | G36: =SUM(G30:G35) -> -13.71682 | H36: =SUM(H30:H35) -> -332.81904 | I36: =SUM(I30:I35) -> -132.88383 | J36: =SUM(J30:J35) -> -132.92233 | K36: =SUM(K30:K35) -> -132.96521 | L36: =SUM(L30:L35) -> -133.01179 | M36: =SUM(M30:M35) -> -133.0555 | ... U36: =SUM(U30:U35) -> -24.541725 | W36: =NPV($D$68,G36:U36)+F36 -> -1271.7613 | X36: =PMT($D$68,15,-W36) -> -130.94406 | Y36: =W36*1000000/7744865 -> -164.20703 | Z36: =W36/$W$36 -> 1
B38: COMA [MUSD] | C38: Operación Comunicaciones UM - HES | F38: =(-'CB_SMMC_Mixto'!B13/1000000)*F$25 -> -0.041122994 | G38: =(-'CB_SMMC_Mixto'!C13/1000000)*G$25 -> -0.059716136 | H38: =(-'CB_SMMC_Mixto'!D13/1000000)*H$25 -> -0.85150144 | I38: =(-'CB_SMMC_Mixto'!E13/1000000)*I$25 -> -1.6200231 | J38: =(-'CB_SMMC_Mixto'!F13/1000000)*J$25 -> -2.3665749 | K38: =(-'CB_SMMC_Mixto'!G13/1000000)*K$25 -> -3.0915869 | L38: =(-'CB_SMMC_Mixto'!H13/1000000)*L$25 -> -3.7954866 | M38: =(-'CB_SMMC_Mixto'!I13/1000000)*M$25 -> -4.4786866 | ... U38: =(-'CB_SMMC_Mixto'!Q13/1000000)*U$25 -> -8.3723666 | W38: =NPV($D$68,G38:U38)+F38 -> -40.721394 | X38: =PMT($D$68,15,-W38) -> -4.1927873 | Y38: =W38*1000000/7744865 -> -5.2578572 | Z38: =W38/$W$43 -> 0.080553907
C39: Operación Comunicaciones DCU - HES | F39: =(-'CB_SMMC_Mixto'!B14/1000000)*F$25 -> 0 | G39: =(-'CB_SMMC_Mixto'!C14/1000000)*G$25 -> 0 | H39: =(-'CB_SMMC_Mixto'!D14/1000000)*H$25 -> -0.10057449 | I39: =(-'CB_SMMC_Mixto'!E14/1000000)*I$25 -> -0.19144737 | J39: =(-'CB_SMMC_Mixto'!F14/1000000)*J$25 -> -0.27982154 | K39: =(-'CB_SMMC_Mixto'!G14/1000000)*K$25 -> -0.36574697 | L39: =(-'CB_SMMC_Mixto'!H14/1000000)*L$25 -> -0.44927672 | M39: =(-'CB_SMMC_Mixto'!I14/1000000)*M$25 -> -0.53045937 | ... U39: =(-'CB_SMMC_Mixto'!Q14/1000000)*U$25 -> -0.99678903 | W39: =NPV($D$68,G39:U39)+F39 -> -4.8198793 | X39: =PMT($D$68,15,-W39) -> -0.49626809 | Y39: =W39*1000000/7744865 -> -0.62233225 | Z39: =W39/$W$43 -> 0.0095345484
C40: Operación HES | F40: =(-'CB_SMMC_Mixto'!B15/1000000)*F$25 -> -0.0093760426 | G40: =(-'CB_SMMC_Mixto'!C15/1000000)*G$25 -> -0.013615279 | H40: =(-'CB_SMMC_Mixto'!D15/1000000)*H$25 -> -6.6683847 | I40: =(-'CB_SMMC_Mixto'!E15/1000000)*I$25 -> -12.869113 | J40: =(-'CB_SMMC_Mixto'!F15/1000000)*J$25 -> -19.069841 | K40: =(-'CB_SMMC_Mixto'!G15/1000000)*K$25 -> -25.270569 | L40: =(-'CB_SMMC_Mixto'!H15/1000000)*L$25 -> -31.471297 | M40: =(-'CB_SMMC_Mixto'!I15/1000000)*M$25 -> -37.672026 | ... U40: =(-'CB_SMMC_Mixto'!Q15/1000000)*U$25 -> -79.017731 | W40: =NPV($D$68,G40:U40)+F40 -> -355.63244 | X40: =PMT($D$68,15,-W40) -> -36.616899 | Y40: =W40*1000000/7744865 -> -45.918481 | Z40: =W40/$W$43 -> 0.703502
C41: Operación MDMS | F41: =(-'CB_SMMC_Mixto'!B16/1000000)*F$25 -> -0.0013307243 | G41: =(-'CB_SMMC_Mixto'!C16/1000000)*G$25 -> -0.0019323912 | H41: =(-'CB_SMMC_Mixto'!D16/1000000)*H$25 -> -0.94643142 | I41: =(-'CB_SMMC_Mixto'!E16/1000000)*I$25 -> -1.8264892 | J41: =(-'CB_SMMC_Mixto'!F16/1000000)*J$25 -> -2.706547 | K41: =(-'CB_SMMC_Mixto'!G16/1000000)*K$25 -> -3.5866048 | L41: =(-'CB_SMMC_Mixto'!H16/1000000)*L$25 -> -4.4666626 | M41: =(-'CB_SMMC_Mixto'!I16/1000000)*M$25 -> -5.3467204 | ... U41: =(-'CB_SMMC_Mixto'!Q16/1000000)*U$25 -> -11.214839 | W41: =NPV($D$68,G41:U41)+F41 -> -50.47425 | X41: =PMT($D$68,15,-W41) -> -5.1969683 | Y41: =W41*1000000/7744865 -> -6.5171246 | Z41: =W41/$W$43 -> 0.099846729
C42: SyM Equipos | F42: =(-'CB_SMMC_Mixto'!B17/1000000)*F$25 -> 0 | G42: =(-'CB_SMMC_Mixto'!C17/1000000)*G$25 -> 0 | H42: =(-'CB_SMMC_Mixto'!D17/1000000)*H$25 -> -1.0069735 | I42: =(-'CB_SMMC_Mixto'!E17/1000000)*I$25 -> -1.9441525 | J42: =(-'CB_SMMC_Mixto'!F17/1000000)*J$25 -> -2.8821106 | K42: =(-'CB_SMMC_Mixto'!G17/1000000)*K$25 -> -3.8208325 | L42: =(-'CB_SMMC_Mixto'!H17/1000000)*L$25 -> -4.7603031 | M42: =(-'CB_SMMC_Mixto'!I17/1000000)*M$25 -> -5.7005078 | ... U42: =(-'CB_SMMC_Mixto'!Q17/1000000)*U$25 -> -11.993148 | W42: =NPV($D$68,G42:U42)+F42 -> -53.869347 | X42: =PMT($D$68,15,-W42) -> -5.5465369 | Y42: =W42*1000000/7744865 -> -6.9554921 | Z42: =W42/$W$43 -> 0.10656281
C43: COMA Total: | F43: =SUM(F38:F42) -> -0.051829761 | G43: =SUM(G38:G42) -> -0.075263807 | H43: =SUM(H38:H42) -> -9.5738655 | I43: =SUM(I38:I42) -> -18.451225 | J43: =SUM(J38:J42) -> -27.304895 | K43: =SUM(K38:K42) -> -36.13534 | L43: =SUM(L38:L42) -> -44.943026 | M43: =SUM(M38:M42) -> -53.7284 | ... U43: =SUM(U38:U42) -> -111.59487 | W43: =NPV($D$68,G43:U43)+F43 -> -505.51731 | X43: =PMT($D$68,15,-W43) -> -52.049459 | Y43: =W43*1000000/7744865 -> -65.271287 | Z43: =W43/$W$43 -> 1
B45: Costos Totales (VI + COMA) | F45: =F36+F43 -> -22.957656 | G45: =G36+G43 -> -13.792084 | H45: =H36+H43 -> -342.39291 | I45: =I36+I43 -> -151.33506 | J45: =J36+J43 -> -160.22723 | K45: =K36+K43 -> -169.10055 | L45: =L36+L43 -> -177.95481 | M45: =M36+M43 -> -186.7839 | ... U45: =U36+U43 -> -136.1366 | W45: =NPV($D$68,G45:U45)+F45 -> -1777.2786 | X45: =PMT($D$68,15,-W45) -> -182.99352 | Y45: =W45*1000000/7744865 -> -229.47832
B47: Beneficios [MUSD] | C47: 1) Lectura remota | F47: 0 | G47: 0 | H47: =('CB_SMMC_Mixto'!D18/1000000)*H$25 -> 3.0718077 | I47: =('CB_SMMC_Mixto'!E18/1000000)*I$25 -> 5.9310377 | J47: =('CB_SMMC_Mixto'!F18/1000000)*J$25 -> 8.7929453 | K47: =('CB_SMMC_Mixto'!G18/1000000)*K$25 -> 11.657531 | L47: =('CB_SMMC_Mixto'!H18/1000000)*L$25 -> 14.524745 | M47: =('CB_SMMC_Mixto'!I18/1000000)*M$25 -> 17.394397 | N47: =('CB_SMMC_Mixto'!J18/1000000)*N$25 -> 20.266753 | O47: =('CB_SMMC_Mixto'!K18/1000000)*O$25 -> 23.141642 | ... U47: =('CB_SMMC_Mixto'!Q18/1000000)*U$25 -> 36.613279 | V47: =W47+W48+W49+W50+W54+W55 -> 1042.3612 | W47: =NPV($D$68,G47:U47)+F47 -> 164.40459 | X47: =PMT($D$68,15,-W47) -> 16.927551 | Y47: =W47*1000000/7744865 -> 21.22756 | Z47: =W47/$W$56 -> 0.11587868
C48: 2) Corte y Reposición remoto | F48: 0 | G48: 0 | H48: =('CB_SMMC_Mixto'!D19/1000000)*H$25 -> 0.2977396 | I48: =('CB_SMMC_Mixto'!E19/1000000)*I$25 -> 0.57484119 | J48: =('CB_SMMC_Mixto'!F19/1000000)*J$25 -> 0.85217026 | K48: =('CB_SMMC_Mixto'!G19/1000000)*K$25 -> 1.129724 | L48: =('CB_SMMC_Mixto'!H19/1000000)*L$25 -> 1.4074967 | M48: =('CB_SMMC_Mixto'!I19/1000000)*M$25 -> 1.6854784 | N48: =('CB_SMMC_Mixto'!J19/1000000)*N$25 -> 1.9636793 | O48: =('CB_SMMC_Mixto'!K19/1000000)*O$25 -> 2.2420877 | ... U48: =('CB_SMMC_Mixto'!Q19/1000000)*U$25 -> 3.5529679 | V48: =PMT(D68,15,-V47) -> 107.32439 | W48: =NPV($D$68,G48:U48)+F48 -> 15.933526 | X48: =PMT($D$68,15,-W48) -> 1.6405598 | Y48: =W48*1000000/7744865 -> 2.0573019 | Z48: =W48/$W$56 -> 0.011230562
C49: 3) Reducción de Pérdidas No Técnicas | F49: 0 | G49: 0 | H49: =('CB_SMMC_Mixto'!D20/1000000)*H$25 -> 11.836647 | I49: =('CB_SMMC_Mixto'!E20/1000000)*I$25 -> 23.199898 | J49: =('CB_SMMC_Mixto'!F20/1000000)*J$25 -> 34.914567 | K49: =('CB_SMMC_Mixto'!G20/1000000)*K$25 -> 46.988265 | L49: =('CB_SMMC_Mixto'!H20/1000000)*L$25 -> 59.4288 | M49: =('CB_SMMC_Mixto'!I20/1000000)*M$25 -> 72.243988 | N49: =('CB_SMMC_Mixto'!J20/1000000)*N$25 -> 85.442122 | O49: =('CB_SMMC_Mixto'!K20/1000000)*O$25 -> 99.031313 | ... U49: =('CB_SMMC_Mixto'!Q20/1000000)*U$25 -> 171.34508 | W49: =NPV($D$68,G49:U49)+F49 -> 713.69488 | X49: =PMT($D$68,15,-W49) -> 73.483997 | Y49: =W49*1000000/7744865 -> 92.150719 | Z49: =W49/$W$56 -> 0.50303961
C50: 4) Reducción del Tiempo de Respuesta ante Fallas | F50: =('CB_SMMC_Mixto'!B21/1000000)*F$25 -> 0.01053559 | G50: =('CB_SMMC_Mixto'!C21/1000000)*G$25 -> 0.015268122 | H50: =('CB_SMMC_Mixto'!D21/1000000)*H$25 -> 0.21771047 | I50: =('CB_SMMC_Mixto'!E21/1000000)*I$25 -> 0.41420482 | J50: =('CB_SMMC_Mixto'!F21/1000000)*J$25 -> 0.60508193 | K50: =('CB_SMMC_Mixto'!G21/1000000)*K$25 -> 0.79045179 | L50: =('CB_SMMC_Mixto'!H21/1000000)*L$25 -> 0.9704237 | M50: =('CB_SMMC_Mixto'!I21/1000000)*M$25 -> 1.1451031 | ... U50: =('CB_SMMC_Mixto'!Q21/1000000)*U$25 -> 2.1406328 | V50: =W53+W52+W51 -> 376.40355 | W50: =NPV($D$68,G50:U50)+F50 -> 10.4116 | X50: =PMT($D$68,15,-W50) -> 1.0720071 | Y50: =W50*1000000/7744865 -> 1.3443229 | Z50: =W50/$W$56 -> 0.0073384961
C51: 5) Reducción del Precio de la Energía | F51: 0 | G51: 0 | H51: =('CB_SMMC_Mixto'!D22/1000000)*H$25 -> 2.9995071 | I51: =('CB_SMMC_Mixto'!E22/1000000)*I$25 -> 5.8790516 | J51: =('CB_SMMC_Mixto'!F22/1000000)*J$25 -> 8.8476483 | K51: =('CB_SMMC_Mixto'!G22/1000000)*K$25 -> 11.907226 | L51: =('CB_SMMC_Mixto'!H22/1000000)*L$25 -> 15.059764 | M51: =('CB_SMMC_Mixto'!I22/1000000)*M$25 -> 18.307241 | N51: =('CB_SMMC_Mixto'!J22/1000000)*N$25 -> 21.651761 | O51: =('CB_SMMC_Mixto'!K22/1000000)*O$25 -> 25.095377 | ... U51: =('CB_SMMC_Mixto'!Q22/1000000)*U$25 -> 43.420302 | V51: =PMT(D68,15,-V50) -> 38.75555 | W51: =NPV($D$68,G51:U51)+F51 -> 180.85635 | X51: =PMT($D$68,15,-W51) -> 18.62147 | Y51: =W51*1000000/7744865 -> 23.351776 | Z51: =W51/$W$56 -> 0.12747452
C52: 6) Reducción del Consumo de Clientes Finales | F52: 0 | G52: 0 | H52: =('CB_SMMC_Mixto'!D23/1000000)*H$25 -> 1.2233144 | I52: =('CB_SMMC_Mixto'!E23/1000000)*I$25 -> 2.3977034 | J52: =('CB_SMMC_Mixto'!F23/1000000)*J$25 -> 3.6084113 | K52: =('CB_SMMC_Mixto'!G23/1000000)*K$25 -> 4.8562248 | L52: =('CB_SMMC_Mixto'!H23/1000000)*L$25 -> 6.1419509 | M52: =('CB_SMMC_Mixto'!I23/1000000)*M$25 -> 7.4663972 | N52: =('CB_SMMC_Mixto'!J23/1000000)*N$25 -> 8.8304208 | O52: =('CB_SMMC_Mixto'!K23/1000000)*O$25 -> 10.23486 | ... U52: =('CB_SMMC_Mixto'!Q23/1000000)*U$25 -> 17.708469 | W52: =NPV($D$68,G52:U52)+F52 -> 73.760178 | X52: =PMT($D$68,15,-W52) -> 7.5945518 | Y52: =W52*1000000/7744865 -> 9.5237525 | Z52: =W52/$W$56 -> 0.051989012
...
