Workbook

Sheet Supuestos y Consideraciones
B2: Supuestos y consideraciones
B4: Posibles variables que definen a un escenario | K4: Parámetros relevantes del Sistema Eléctrico en Chile
B5: 1) Extensión del despliegue (% de consumidores). | K5: Parámetro | Q5: Unidad | R5: Valor | S5: Comentario
B6: 2) Tiempo de plazo para el despliegue. | K6: Variación proyectada del consumo de energía | Q6: %
B7: 3) Número de funcionalidades del Sistema de Medición Inteligente. | K7: Variación proyectada de los precios de la energía | Q7: %
B8: 4) Densidad de clientes en el despliegue (Urbano vs Rural). | K8: Transferencia de carga de punta | Q8: %
K9: Pérdidas eléctricas en niveles de transmisión y distribución | Q9: %
K10: Minutos no suministrados estimados | Q10: Cantidad
B11: Escenario 0 (Caso Base, sin despliegue): | K11: Valor de Energía No Suministrada; valor del suministro | Q11: $/kWh
B12: Variables | H12: Valor | K12: Tasa de descuento | Q12: %
B13: 1) Extensión del despliegue (% de consumidores). | H13: 0 | K13: Costos de hardware (p. ej, medidor inteligente, módem GPRS/PLC, etc.) | Q13: $
B14: 2) Tiempo de plazo para el despliegue. | H14: 2030 | K14: Número de medidores inteligentes a instalar | Q14: Cantidad
B15: 3) Número de funcionalidades del Sistema de Medición Inteligente. | H15: 0 | K15: Costos de instalación del sistema de medición inteligente | Q15: $
K16: Vida útil del sistema de medición inteligente | Q16: Años
K17: Costos de lectura de medidores | Q17: $/año
B18: Escenario 1: | K18: Tasa de éxito de telecomunicación | Q18: %
B19: Variables | H19: Valor | K19: Tasa de inflación | Q19: %
B20: 1) Extensión del despliegue (% de consumidores). | H20: 0.8 | K20: Reducción de costos asociada a la madurez tecnológica | Q20: %
B21: 2) Tiempo de plazo para el despliegue. | H21: 2030 | K21: Calendario de implementación | Q21: Cantidad/año
B22: 3) Número de funcionalidades del Sistema de Medición Inteligente. | H22: 10 | K22: Porcentaje de medidores ubicados en zonas rurales vs urbanas | Q22: %
K23: Costos de carbono | Q23: $/ton

Sheet CB_SMI_Mixto
A1: Concepto | B1: Periodo 0 | C1: Periodo 1 | D1: Periodo 2 | E1: Periodo 3 | F1: Periodo 4 | G1: Periodo 5 | H1: Periodo 6 | I1: Periodo 7 | J1: Periodo 8 | K1: Periodo 9 | L1: Periodo 10 | M1: Periodo 11 | N1: Periodo 12 | O1: Periodo 13 | P1: Periodo 14 | Q1: Periodo 15
A2: Energía facturada anual [MWh/año] | B2: 34765766 | C2: 35815692 | D2: 36897326 | E2: 38011625 | F2: 39159576 | G2: 40342196 | H2: 41560530 | I2: 42815658 | J2: 44108691 | K2: 45440773 | L2: 46813085 | M2: 48226840 | N2: 49683290 | O2: 51183726 | P2: 52729474 | Q2: 54321904
A3: Cantidad UM 1F | B3: 22317 | C3: 58 | D3: 58 | E3: 59 | F3: 59 | G3: 62 | H3: 62 | I3: 62 | J3: 62 | K3: 62 | L3: 62 | M3: 62 | N3: 62 | O3: 63 | P3: 64 | Q3: 64
A4: Cantidad UM 3F Directa | B4: 0 | C4: 0 | D4: 0 | E4: 0 | F4: 0 | G4: 0 | H4: 0 | I4: 0 | J4: 0 | K4: 0 | L4: 0 | M4: 0 | N4: 0 | O4: 0 | P4: 0 | Q4: 0
A5: Cantidad UM 3F Indirecta | B5: 215824 | C5: 734 | D5: 734 | E5: 739 | F5: 741 | G5: 750 | H5: 750 | I5: 755 | J5: 757 | K5: 757 | L5: 757 | M5: 762 | N5: 768 | O5: 774 | P5: 780 | Q5: 788
A6: Cantidad DCU | B6: 0 | C6: 0 | D6: 0 | E6: 0 | F6: 0 | G6: 0 | H6: 0 | I6: 0 | J6: 0 | K6: 0 | L6: 0 | M6: 0 | N6: 0 | O6: 0 | P6: 0 | Q6: 0
A7: Inversión UM 1F [USD/equipo] | B7: 181.40918 | C7: 175.08079 | D7: 175.08079 | E7: 174.30668 | F7: 174.30668 | G7: 173.3395 | H7: 173.3395 | I7: 173.3395 | J7: 173.3395 | K7: 173.3395 | L7: 173.3395 | M7: 173.3395 | N7: 173.3395 | O7: 173.53149 | P7: 173.71748 | Q7: 173.71748
A8: Inversión UM 3F Directa [USD/equipo] | B8: 0 | C8: 0 | D8: 0 | E8: 0 | F8: 0 | G8: 0 | H8: 0 | I8: 0 | J8: 0 | K8: 0 | L8: 0 | M8: 0 | N8: 0 | O8: 0 | P8: 0 | Q8: 0
A9: Inversión UM 3F Indirecta [USD/equipo] | B9: 789.11275 | C9: 747.70341 | D9: 747.70341 | E9: 747.58392 | F9: 747.671 | G9: 747.89109 | H9: 747.89109 | I9: 747.93781 | J9: 747.85763 | K9: 747.85763 | L9: 747.85763 | M9: 747.90414 | N9: 747.99157 | O9: 747.99721 | P9: 747.92295 | Q9: 747.77303
A10: Inversión DCU [USD/equipo] | B10: 0 | C10: 0 | D10: 0 | E10: 0 | F10: 0 | G10: 0 | H10: 0 | I10: 0 | J10: 0 | K10: 0 | L10: 0 | M10: 0 | N10: 0 | O10: 0 | P10: 0 | Q10: 0
A11: Inversión SGO [USD] | B11: 4370125.5 | C11: 14533.992 | D11: 14533.992 | E11: 14644.098 | F11: 14680.8 | G11: 14901.012 | H11: 14901.012 | I11: 14992.767 | J11: 15029.469 | K11: 15029.469 | L11: 15029.469 | M11: 15121.224 | N11: 15231.33 | O11: 15359.787 | P11: 15488.244 | Q11: 15635.052
A12: Inversión MDMS [USD] | B12: 328383.91 | C12: 1092.1263 | D12: 1092.1263 | E12: 1100.4 | F12: 1103.1579 | G12: 1119.7053 | H12: 1119.7053 | I12: 1126.6 | J12: 1129.3579 | K12: 1129.3579 | L12: 1129.3579 | M12: 1136.2526 | N12: 1144.5263 | O12: 1154.1789 | P12: 1163.8316 | Q12: 1174.8632
A13: Operación Comunicaciones [USD/año] | B13: 0 | C13: 0 | D13: 0 | E13: 0 | F13: 0 | G13: 0 | H13: 0 | I13: 0 | J13: 0 | K13: 0 | L13: 0 | M13: 0 | N13: 0 | O13: 0 | P13: 0 | Q13: 0
... A26: Ahorro por inversión evitada [USD/año] | B26: 14938965 | C26: 14949967 | D26: 14961276 | E26: 15126164 | F26: 15161638 | G26: 15184728 | H26: 15201352 | I26: 15217576 | J26: 15343357 | K26: 15375861 | L26: 15401600 | M26: 15427401 | N26: 15457996 | O26: 15503510 | P26: 15549159 | Q26: 15594942

Sheet Flujo SMI_Mixto
B2: Escenario de implementación | G2: Supuestos y Consideraciones
B4: Densidad de clientes | D4: Tecnología | G4: Tasa de descuento | J4: 0.06 | K4: % | R4: Dólar | S4: 959.36 | T4: USD/$ | U4: 45946
B5: Alta | D5: Mixto | G5: Vida útil del proyecto | J5: 15 | K5: años | R5: UF | S5: 39521.26 | T5: UF/$ | U5: 45946
B6: Media | D6: Mixto | G6: Meta de despligue | J6: 3 | K6: años
B7: Baja | D7: Mixto | G7: Objetivo de despligue UM 1F | J7: =(SUMIF($F$12:$U$12,"<="&$J$6,$F$17:$U$17)) / ($J$6) -> 7497.3333 | K7: UM/año | L7: ="Razonable para chile en torno a 1M y 1,5M por año." -> Razonable para chile en torno a 1M y 1,5M por año.
B8: Muy Baja | D8: Mixto | G8: Objetivo de despligue UM 3F Directa | J8: =(SUMIF($F$12:$U$12,"<="&$J$6,$F$18:$U$18)) / ($J$6) -> 0 | K8: UM/año | L8: ="Razonable para chile en torno a 1M y 1,5M por año." -> Razonable para chile en torno a 1M y 1,5M por año.
B9: Extremadamente Baja | D9: Mixto | G9: Objetivo de despligue UM 3F Indirecta | J9: =(SUMIF($F$12:$U$12,"<="&$J$6,$F$19:$U$19)) / ($J$6) -> 72677 | K9: UM/año | L9: ="Razonable para chile en torno a 1M y 1,5M por año." -> Razonable para chile en torno a 1M y 1,5M por año.
B12: Despligue SMI Chile | E12: Periodo | F12: 0 | G12: 1 | H12: 2 | I12: 3 | J12: 4 | K12: 5 | L12: 6 | M12: 7 | N12: 8 | O12: 9 | P12: 10 | Q12: 11 | R12: 12 | S12: 13 | T12: 14 | U12: 15
E13: Año | F13: 2025 | G13: 2026 | H13: 2027 | I13: 2028 | J13: 2029 | K13: 2030 | L13: 2031 | M13: 2032 | N13: 2033 | O13: 2034 | P13: 2035 | Q13: 2036 | R13: 2037 | S13: 2038 | T13: 2039 | U13: 2040
B15: Datos de despliegue | C15: Energía Facturada anual [GWh] | F15: =CB_SMI_Mixto!B2/1000 -> 34765.766 | G15: =CB_SMI_Mixto!C2/1000 -> 35815.692 | H15: =CB_SMI_Mixto!D2/1000 -> 36897.326 | I15: =CB_SMI_Mixto!E2/1000 -> 38011.625 | J15: =CB_SMI_Mixto!F2/1000 -> 39159.576 | K15: =CB_SMI_Mixto!G2/1000 -> 40342.196 | L15: =CB_SMI_Mixto!H2/1000 -> 41560.53 | M15: =CB_SMI_Mixto!I2/1000 -> 42815.658 | ... U15: =CB_SMI_Mixto!Q2/1000 -> 54321.904
C17: UM 1F [N° Equipos] | F17: =CB_SMI_Mixto!B3 -> 22317 | G17: =CB_SMI_Mixto!C3 -> 58 | H17: =CB_SMI_Mixto!D3 -> 58 | I17: =CB_SMI_Mixto!E3 -> 59 | J17: =CB_SMI_Mixto!F3 -> 59 | K17: =CB_SMI_Mixto!G3 -> 62 | L17: =CB_SMI_Mixto!H3 -> 62 | M17: =CB_SMI_Mixto!I3 -> 62 | ... U17: =CB_SMI_Mixto!Q3 -> 64
C18: UM 3F Directa [N° Equipos] | F18: =CB_SMI_Mixto!B4 -> 0 | G18: =CB_SMI_Mixto!C4 -> 0 | H18: =CB_SMI_Mixto!D4 -> 0 | I18: =CB_SMI_Mixto!E4 -> 0 | J18: =CB_SMI_Mixto!F4 -> 0 | K18: =CB_SMI_Mixto!G4 -> 0 | L18: =CB_SMI_Mixto!H4 -> 0 | M18: =CB_SMI_Mixto!I4 -> 0 | ... U18: =CB_SMI_Mixto!Q4 -> 0
C19: UM 3F Indirecta [N° Equipos] | F19: =CB_SMI_Mixto!B5 -> 215824 | G19: =CB_SMI_Mixto!C5 -> 734 | H19: =CB_SMI_Mixto!D5 -> 734 | I19: =CB_SMI_Mixto!E5 -> 739 | J19: =CB_SMI_Mixto!F5 -> 741 | K19: =CB_SMI_Mixto!G5 -> 750 | L19: =CB_SMI_Mixto!H5 -> 750 | M19: =CB_SMI_Mixto!I5 -> 755 | ... U19: =CB_SMI_Mixto!Q5 -> 788
B21: Despliegue | C21: UM 1F instalados | F21: 0 | G21: =IF(G$12<=$J$6,$J7,G17) -> 7497.3333 | H21: =IF(H$12<=$J$6,$J7,H17) -> 7497.3333 | I21: =IF(I$12<=$J$6,$J7,I17) -> 7497.3333 | J21: =IF(J$12<=$J$6,$J7,J17) -> 59 | K21: =IF(K$12<=$J$6,$J7,K17) -> 62 | L21: =IF(L$12<=$J$6,$J7,L17) -> 62 | M21: =IF(M$12<=$J$6,$J7,M17) -> 62 | N21: =IF(N$12<=$J$6,$J7,N17) -> 62 | ... U21: =IF(U$12<=$J$6,$J7,U17) -> 64
C22: UM 3F Directa instalados | F22: 0 | G22: =IF(G$12<=$J$6,$J8,G18) -> 0 | H22: =IF(H$12<=$J$6,$J8,H18) -> 0 | I22: =IF(I$12<=$J$6,$J8,I18) -> 0 | J22: =IF(J$12<=$J$6,$J8,J18) -> 0 | K22: =IF(K$12<=$J$6,$J8,K18) -> 0 | L22: =IF(L$12<=$J$6,$J8,L18) -> 0 | M22: =IF(M$12<=$J$6,$J8,M18) -> 0 | N22: =IF(N$12<=$J$6,$J8,N18) -> 0 | ... U22: =IF(U$12<=$J$6,$J8,U18) -> 0
C23: UM 3F Indirecta instalados | F23: 0 | G23: =IF(G$12<=$J$6,$J9,G19) -> 72677 | H23: =IF(H$12<=$J$6,$J9,H19) -> 72677 | I23: =IF(I$12<=$J$6,$J9,I19) -> 72677 | J23: =IF(J$12<=$J$6,$J9,J19) -> 741 | K23: =IF(K$12<=$J$6,$J9,K19) -> 750 | L23: =IF(L$12<=$J$6,$J9,L19) -> 750 | M23: =IF(M$12<=$J$6,$J9,M19) -> 755 | N23: =IF(N$12<=$J$6,$J9,N19) -> 757 | ... U23: =IF(U$12<=$J$6,$J9,U19) -> 788
C24: UM faltantes por instalar | F24: =SUM(F17:F19) -> 238141 | G24: =SUM(F24,G17:G19)-SUM(G21:G23) -> 158758.67 | H24: =SUM(G24,H17:H19)-SUM(H21:H23) -> 79376.333 | I24: =SUM(H24,I17:I19)-SUM(I21:I23) -> 0 | J24: =SUM(I24,J17:J19)-SUM(J21:J23) -> 0 | K24: =SUM(J24,K17:K19)-SUM(K21:K23) -> 0 | L24: =SUM(K24,L17:L19)-SUM(L21:L23) -> 0 | M24: =SUM(L24,M17:M19)-SUM(M21:M23) -> 0 | N24: =SUM(M24,N17:N19)-SUM(N21:N23) -> 0 | ... U24: =SUM(T24,U17:U19)-SUM(U21:U23) -> 0
C25: % de avance | F25: 0 | G25: =IF(G$12<=$J$6,SUM($F$21:G23)/SUM($F$17:G19),1) -> 0.33555153 | H25: =IF(H$12<=$J$6,SUM($F$21:H23)/SUM($F$17:H19),1) -> 0.66888588 | I25: =IF(I$12<=$J$6,SUM($F$21:I23)/SUM($F$17:I19),1) -> 1 | J25: =IF(J$12<=$J$6,SUM($F$21:J23)/SUM($F$17:J19),1) -> 1 | K25: =IF(K$12<=$J$6,SUM($F$21:K23)/SUM($F$17:K19),1) -> 1 | L25: =IF(L$12<=$J$6,SUM($F$21:L23)/SUM($F$17:L19),1) -> 1 | M25: =IF(M$12<=$J$6,SUM($F$21:M23)/SUM($F$17:M19),1) -> 1 | N25: =IF(N$12<=$J$6,SUM($F$21:N23)/SUM($F$17:N19),1) -> 1 | ... U25: =IF(U$12<=$J$6,SUM($F$21:U23)/SUM($F$17:U19),1) -> 1
B27: Flujo de caja [MUSD] | E27: Periodo | F27: 0 | G27: 1 | H27: 2 | I27: 3 | J27: 4 | K27: 5 | L27: 6 | M27: 7 | N27: 8 | O27: 9 | P27: 10 | Q27: 11 | R27: 12 | S27: 13 | T27: 14 | U27: 15
E28: Año | F28: 2025 | G28: 2026 | H28: 2027 | I28: 2028 | J28: 2029 | K28: 2030 | L28: 2031 | M28: 2032 | N28: 2033 | O28: 2034 | P28: 2035 | Q28: 2036 | R28: 2037 | S28: 2038 | T28: 2039 | U28: 2040 | W28: VAN [MUSD] | X28: AVAN [MUSD] | Y28: VAN [USD/# Clientes] | Z28: Participación %
B30: VI [MUSD] | C30: UM 1F | F30: 0 | G30: =((-CB_SMI_Mixto!C7)*G21)/1000000 -> -1.3126391 | H30: =((-CB_SMI_Mixto!D7)*H21)/1000000 -> -1.3126391 | I30: =((-CB_SMI_Mixto!E7)*I21)/1000000 -> -1.3068353 | J30: =((-CB_SMI_Mixto!F7)*J21)/1000000 -> -0.010284094 | K30: =((-CB_SMI_Mixto!G7)*K21)/1000000 -> -0.010747049 | L30: =((-CB_SMI_Mixto!H7)*L21)/1000000 -> -0.010747049 | M30: =((-CB_SMI_Mixto!I7)*M21)/1000000 -> -0.010747049 | N30: =((-CB_SMI_Mixto!J7)*N21)/1000000 -> -0.010747049 | ... U30: =((-CB_SMI_Mixto!Q7)*U21)/1000000 -> -0.011117919 | W30: =NPV($D$67,G30:U30)+F30 -> -3.5795169 | X30: =PMT($D$67,15,-W30) -> -0.36855696 | Y30: =W30*1000000/7744865 -> -0.46217939 | Z30: =W30/$W$36 -> 0.022701612
C31: UM 3F Directa | F31: 0 | G31: =((-CB_SMI_Mixto!C8)*G22)/1000000 -> 0 | H31: =((-CB_SMI_Mixto!D8)*H22)/1000000 -> 0 | I31: =((-CB_SMI_Mixto!E8)*I22)/1000000 -> 0 | J31: =((-CB_SMI_Mixto!F8)*J22)/1000000 -> 0 | K31: =((-CB_SMI_Mixto!G8)*K22)/1000000 -> 0 | L31: =((-CB_SMI_Mixto!H8)*L22)/1000000 -> 0 | M31: =((-CB_SMI_Mixto!I8)*M22)/1000000 -> 0 | N31: =((-CB_SMI_Mixto!J8)*N22)/1000000 -> 0 | ... U31: =((-CB_SMI_Mixto!Q8)*U22)/1000000 -> 0 | W31: =NPV($D$67,G31:U31)+F31 -> 0 | X31: =PMT($D$67,15,-W31) -> 0 | Y31: =W31*1000000/7744865 -> 0 | Z31: =W31/$W$36 -> 0
C32: UM 3F Indirecta | F32: 0 | G32: =((-CB_SMI_Mixto!C9)*G23)/1000000 -> -54.34084 | H32: =((-CB_SMI_Mixto!D9)*H23)/1000000 -> -54.34084 | I32: =((-CB_SMI_Mixto!E9)*I23)/1000000 -> -54.332156 | J32: =((-CB_SMI_Mixto!F9)*J23)/1000000 -> -0.55402421 | K32: =((-CB_SMI_Mixto!G9)*K23)/1000000 -> -0.56091832 | L32: =((-CB_SMI_Mixto!H9)*L23)/1000000 -> -0.56091832 | M32: =((-CB_SMI_Mixto!I9)*M23)/1000000 -> -0.56469305 | N32: =((-CB_SMI_Mixto!J9)*N23)/1000000 -> -0.56612823 | ... U32: =((-CB_SMI_Mixto!Q9)*U23)/1000000 -> -0.58924515 | W32: =NPV($D$67,G32:U32)+F32 -> -149.24284 | X32: =PMT($D$67,15,-W32) -> -15.366456 | Y32: =W32*1000000/7744865 -> -19.269909 | Z32: =W32/$W$36 -> 0.94651126
C33: DCU | F33: =((-CB_SMI_Mixto!B10)*CB_SMI_Mixto!B6)/1000000 -> 0 | G33: =((-CB_SMI_Mixto!C10)*CB_SMI_Mixto!C6)/1000000 -> 0 | H33: =((-CB_SMI_Mixto!D10)*CB_SMI_Mixto!D6)/1000000 -> 0 | I33: =((-CB_SMI_Mixto!E10)*CB_SMI_Mixto!E6)/1000000 -> 0 | J33: =((-CB_SMI_Mixto!F10)*CB_SMI_Mixto!F6)/1000000 -> 0 | K33: =((-CB_SMI_Mixto!G10)*CB_SMI_Mixto!G6)/1000000 -> 0 | L33: =((-CB_SMI_Mixto!H10)*CB_SMI_Mixto!H6)/1000000 -> 0 | M33: =((-CB_SMI_Mixto!I10)*CB_SMI_Mixto!I6)/1000000 -> 0 | ... U33: =((-CB_SMI_Mixto!Q10)*CB_SMI_Mixto!Q6)/1000000 -> 0 | W33: =NPV($D$67,G33:U33)+F33 -> 0 | X33: =PMT($D$67,15,-W33) -> 0 | Y33: =W33*1000000/7744865 -> 0 | Z33: =W33/$W$36 -> 0
C34: HES | F34: =(-CB_SMI_Mixto!B11)/1000000 -> -4.3701255 | G34: =(-CB_SMI_Mixto!C11)/1000000 -> -0.014533992 | H34: =(-CB_SMI_Mixto!D11)/1000000 -> -0.014533992 | I34: =(-CB_SMI_Mixto!E11)/1000000 -> -0.014644098 | J34: =(-CB_SMI_Mixto!F11)/1000000 -> -0.0146808 | K34: =(-CB_SMI_Mixto!G11)/1000000 -> -0.014901012 | L34: =(-CB_SMI_Mixto!H11)/1000000 -> -0.014901012 | M34: =(-CB_SMI_Mixto!I11)/1000000 -> -0.014992767 | ... U34: =(-CB_SMI_Mixto!Q11)/1000000 -> -0.015635052 | W34: =NPV($D$67,G34:U34)+F34 -> -4.5151355 | X34: =PMT($D$67,15,-W34) -> -0.46489083 | Y34: =W34*1000000/7744865 -> -0.5829844 | Z34: =W34/$W$36 -> 0.028635387
C35: MDMS | F35: =(-CB_SMI_Mixto!B12)/1000000 -> -0.32838391 | G35: =(-CB_SMI_Mixto!C12)/1000000 -> -0.0010921263 | H35: =(-CB_SMI_Mixto!D12)/1000000 -> -0.0010921263 | I35: =(-CB_SMI_Mixto!E12)/1000000 -> -0.0011004 | J35: =(-CB_SMI_Mixto!F12)/1000000 -> -0.0011031579 | K35: =(-CB_SMI_Mixto!G12)/1000000 -> -0.0011197053 | L35: =(-CB_SMI_Mixto!H12)/1000000 -> -0.0011197053 | M35: =(-CB_SMI_Mixto!I12)/1000000 -> -0.0011266 | ... U35: =(-CB_SMI_Mixto!Q12)/1000000 -> -0.0011748632 | W35: =NPV($D$67,G35:U35)+F35 -> -0.33928037 | X35: =PMT($D$67,15,-W35) -> -0.034933245 | Y35: =W35*1000000/7744865 -> -0.043807139 | Z35: =W35/$W$36 -> 0.002151746
C36: VI Total: | F36: =SUM(F30:F35) -> -4.6985094 | G36: =SUM(G30:G35) -> -55.669106 | H36: =SUM(H30:H35) -> -55.669106 | I36: =SUM(I30:I35) -> -55.654736 | J36: =SUM(J30:J35) -> -0.58009226 | K36: =SUM(K30:K35) -> -0.58768609 | L36: =SUM(L30:L35) -> -0.58768609 | M36: =SUM(M30:M35) -> -0.59155946 | ... U36: =SUM(U30:U35) -> -0.61717298 | W36: =NPV($D$67,G36:U36)+F36 -> -157.67678 | X36: =PMT($D$67,15,-W36) -> -16.234837 | Y36: =W36*1000000/7744865 -> -20.35888 | Z36: =W36/$W$36 -> 1
B38: COMA [MUSD] | C38: Operación Comunicaciones UM - SGO | F38: 0 | G38: =(-CB_SMI_Mixto!C13/1000000)*G$25 -> 0 | H38: =(-CB_SMI_Mixto!D13/1000000)*H$25 -> 0 | I38: =(-CB_SMI_Mixto!E13/1000000)*I$25 -> 0 | J38: =(-CB_SMI_Mixto!F13/1000000)*J$25 -> 0 | K38: =(-CB_SMI_Mixto!G13/1000000)*K$25 -> 0 | L38: =(-CB_SMI_Mixto!H13/1000000)*L$25 -> 0 | M38: =(-CB_SMI_Mixto!I13/1000000)*M$25 -> 0 | N38: =(-CB_SMI_Mixto!J13/1000000)*N$25 -> 0 | ... U38: =(-CB_SMI_Mixto!Q13/1000000)*U$25 -> 0 | W38: =NPV($D$67,G38:U38)+F38 -> 0 | X38: =PMT($D$67,15,-W38) -> 0 | Y38: =W38*1000000/7744865 -> 0 | Z38: =W38/$W$43 -> 0
C39: Operación Comunicaciones DCU - SGO | F39: 0 | G39: =(-CB_SMI_Mixto!C14/1000000)*G$25 -> -1.3433597 | H39: =(-CB_SMI_Mixto!D14/1000000)*H$25 -> -2.677843 | I39: =(-CB_SMI_Mixto!E14/1000000)*I$25 -> -4.0034378 | J39: =(-CB_SMI_Mixto!F14/1000000)*J$25 -> -4.0034378 | K39: =(-CB_SMI_Mixto!G14/1000000)*K$25 -> -4.0034378 | L39: =(-CB_SMI_Mixto!H14/1000000)*L$25 -> -4.0034378 | M39: =(-CB_SMI_Mixto!I14/1000000)*M$25 -> -4.0034378 | N39: =(-CB_SMI_Mixto!J14/1000000)*N$25 -> -4.0034378 | ... U39: =(-CB_SMI_Mixto!Q14/1000000)*U$25 -> -4.0034378 | W39: =NPV($D$67,G39:U39)+F39 -> -35.193102 | X39: =PMT($D$67,15,-W39) -> -3.6235791 | Y39: =W39*1000000/7744865 -> -4.5440562 | Z39: =W39/$W$43 -> 0.61274697
C40: Operación HES | F40: 0 | G40: =(-CB_SMI_Mixto!C15/1000000)*G$25 -> -0.64021799 | H40: =(-CB_SMI_Mixto!D15/1000000)*H$25 -> -1.280436 | I40: =(-CB_SMI_Mixto!E15/1000000)*I$25 -> -1.920654 | J40: =(-CB_SMI_Mixto!F15/1000000)*J$25 -> -1.9270422 | K40: =(-CB_SMI_Mixto!G15/1000000)*K$25 -> -1.9335263 | L40: =(-CB_SMI_Mixto!H15/1000000)*L$25 -> -1.9400104 | M40: =(-CB_SMI_Mixto!I15/1000000)*M$25 -> -1.9465344 | N40: =(-CB_SMI_Mixto!J15/1000000)*N$25 -> -1.9530744 | ... U40: =(-CB_SMI_Mixto!Q15/1000000)*U$25 -> -1.9995889 | W40: =NPV($D$67,G40:U40)+F40 -> -17.142575 | X40: =PMT($D$67,15,-W40) -> -1.7650469 | Y40: =W40*1000000/7744865 -> -2.2134117 | Z40: =W40/$W$43 -> 0.29846931
C41: Operación MDMS | F41: 0 | G41: =(-CB_SMI_Mixto!C16/1000000)*G$25 -> -0.090864948 | H41: =(-CB_SMI_Mixto!D16/1000000)*H$25 -> -0.1817299 | I41: =(-CB_SMI_Mixto!E16/1000000)*I$25 -> -0.27259484 | J41: =(-CB_SMI_Mixto!F16/1000000)*J$25 -> -0.27350152 | K41: =(-CB_SMI_Mixto!G16/1000000)*K$25 -> -0.27442179 | L41: =(-CB_SMI_Mixto!H16/1000000)*L$25 -> -0.27534206 | M41: =(-CB_SMI_Mixto!I16/1000000)*M$25 -> -0.276268 | N41: =(-CB_SMI_Mixto!J16/1000000)*N$25 -> -0.27719621 | ... U41: =(-CB_SMI_Mixto!Q16/1000000)*U$25 -> -0.28379793 | W41: =NPV($D$67,G41:U41)+F41 -> -2.4330137 | X41: =PMT($D$67,15,-W41) -> -0.25050982 | Y41: =W41*1000000/7744865 -> -0.3141454 | Z41: =W41/$W$43 -> 0.042361193
C42: SyM Equipos | F42: 0 | G42: =(-CB_SMI_Mixto!C17/1000000)*G$25 -> -0.099576522 | H42: =(-CB_SMI_Mixto!D17/1000000)*H$25 -> -0.19915304 | I42: =(-CB_SMI_Mixto!E17/1000000)*I$25 -> -0.29872957 | J42: =(-CB_SMI_Mixto!F17/1000000)*J$25 -> -0.29972317 | K42: =(-CB_SMI_Mixto!G17/1000000)*K$25 -> -0.30073167 | L42: =(-CB_SMI_Mixto!H17/1000000)*L$25 -> -0.30174017 | M42: =(-CB_SMI_Mixto!I17/1000000)*M$25 -> -0.30275489 | N42: =(-CB_SMI_Mixto!J17/1000000)*N$25 -> -0.30377209 | ... U42: =(-CB_SMI_Mixto!Q17/1000000)*U$25 -> -0.31100674 | W42: =NPV($D$67,G42:U42)+F42 -> -2.6662762 | X42: =PMT($D$67,15,-W42) -> -0.27452717 | Y42: =W42*1000000/7744865 -> -0.34426374 | Z42: =W42/$W$43 -> 0.046422525
C43: COMA Total: | F43: =SUM(F38:F42) -> 0 | G43: =SUM(G38:G42) -> -2.1740191 | H43: =SUM(H38:H42) -> -4.3391619 | I43: =SUM(I38:I42) -> -6.4954161 | J43: =SUM(J38:J42) -> -6.5037047 | K43: =SUM(K38:K42) -> -6.5121175 | L43: =SUM(L38:L42) -> -6.5205304 | M43: =SUM(M38:M42) -> -6.5289951 | ... U43: =SUM(U38:U42) -> -6.5978313 | W43: =NPV($D$67,G43:U43)+F43 -> -57.434967 | X43: =PMT($D$67,15,-W43) -> -5.9136629 | Y43: =W43*1000000/7744865 -> -7.4158771 | Z43: =W43/$W$43 -> 1
B45: Costos Totales (VI + COMA) | F45: =F36+F43 -> -4.6985094 | G45: =G36+G43 -> -57.843125 | H45: =H36+H43 -> -60.008267 | I45: =I36+I43 -> -62.150152 | J45: =J36+J43 -> -7.0837969 | K45: =K36+K43 -> -7.0998036 | L45: =L36+L43 -> -7.1082165 | M45: =M36+M43 -> -7.1205545 | ... U45: =U36+U43 -> -7.2150043 | W45: =NPV($D$67,G45:U45)+F45 -> -215.11174 | X45: =PMT($D$67,15,-W45) -> -22.1485 | Y45: =W45*1000000/7744865 -> -27.774757
B47: Beneficios [MUSD] | C47: Ahorro de lectura pedestre | F47: 0 | G47: =(CB_SMI_Mixto!C18/1000000)*G$25 -> 0 | H47: =(CB_SMI_Mixto!D18/1000000)*H$25 -> 0 | I47: =(CB_SMI_Mixto!E18/1000000)*I$25 -> 0 | J47: =(CB_SMI_Mixto!F18/1000000)*J$25 -> 0 | K47: =(CB_SMI_Mixto!G18/1000000)*K$25 -> 0 | L47: =(CB_SMI_Mixto!H18/1000000)*L$25 -> 0 | M47: =(CB_SMI_Mixto!I18/1000000)*M$25 -> 0 | N47: =(CB_SMI_Mixto!J18/1000000)*N$25 -> 0 | ... U47: =(CB_SMI_Mixto!Q18/1000000)*U$25 -> 0 | W47: =NPV($D$67,G47:U47)+F47 -> 0 | X47: =PMT($D$67,15,-W47) -> 0 | Y47: =W47*1000000/7744865 -> 0 | Z47: =W47/$W$56 -> 0
C48: Corte y Reposición remoto | F48: 0 | G48: =(CB_SMI_Mixto!C19/1000000)*G$25 -> 0 | H48: =(CB_SMI_Mixto!D19/1000000)*H$25 -> 0 | I48: =(CB_SMI_Mixto!E19/1000000)*I$25 -> 0 | J48: =(CB_SMI_Mixto!F19/1000000)*J$25 -> 0 | K48: =(CB_SMI_Mixto!G19/1000000)*K$25 -> 0 | L48: =(CB_SMI_Mixto!H19/1000000)*L$25 -> 0 | M48: =(CB_SMI_Mixto!I19/1000000)*M$25 -> 0 | N48: =(CB_SMI_Mixto!J19/1000000)*N$25 -> 0 | ... U48: =(CB_SMI_Mixto!Q19/1000000)*U$25 -> 0 | W48: =NPV($D$67,G48:U48)+F48 -> 0 | X48: =PMT($D$67,15,-W48) -> 0 | Y48: =W48*1000000/7744865 -> 0 | Z48: =W48/$W$56 -> 0
C49: Reducción de Pérdidas No Técnicas (PNT) | F49: 0 | G49: =(CB_SMI_Mixto!C20/1000000)*G$25 -> 0 | H49: =(CB_SMI_Mixto!D20/1000000)*H$25 -> 0 | I49: =(CB_SMI_Mixto!E20/1000000)*I$25 -> 0 | J49: =(CB_SMI_Mixto!F20/1000000)*J$25 -> 0 | K49: =(CB_SMI_Mixto!G20/1000000)*K$25 -> 0 | L49: =(CB_SMI_Mixto!H20/1000000)*L$25 -> 0 | M49: =(CB_SMI_Mixto!I20/1000000)*M$25 -> 0 | N49: =(CB_SMI_Mixto!J20/1000000)*N$25 -> 0 | ... U49: =(CB_SMI_Mixto!Q20/1000000)*U$25 -> 0 | W49: =NPV($D$67,G49:U49)+F49 -> 0 | X49: =PMT($D$67,15,-W49) -> 0 | Y49: =W49*1000000/7744865 -> 0 | Z49: =W49/$W$56 -> 0
C50: Reducción del tiempo de respuesta ante Fallas | F50: 0 | G50: =(CB_SMI_Mixto!C21/1000000)*G$25 -> 0.71829259 | H50: =(CB_SMI_Mixto!D21/1000000)*H$25 -> 1.431839 | I50: =(CB_SMI_Mixto!E21/1000000)*I$25 -> 2.1406328 | J50: =(CB_SMI_Mixto!F21/1000000)*J$25 -> 2.1406328 | K50: =(CB_SMI_Mixto!G21/1000000)*K$25 -> 2.1406328 | L50: =(CB_SMI_Mixto!H21/1000000)*L$25 -> 2.1406328 | M50: =(CB_SMI_Mixto!I21/1000000)*M$25 -> 2.1406328 | N50: =(CB_SMI_Mixto!J21/1000000)*N$25 -> 2.1406328 | ... U50: =(CB_SMI_Mixto!Q21/1000000)*U$25 -> 2.1406328 | W50: =NPV($D$67,G50:U50)+F50 -> 18.817704 | X50: =PMT($D$67,15,-W50) -> 1.9375228 | Y50: =W50*1000000/7744865 -> 2.4297007 | Z50: =W50/$W$56 -> 0.12287878
C51: Gestión del consumo | F51: 0 | G51: =(CB_SMI_Mixto!C22/1000000)*G$25 -> 0 | H51: =(CB_SMI_Mixto!D22/1000000)*H$25 -> 0 | I51: =(CB_SMI_Mixto!E22/1000000)*I$25 -> 0 | J51: =(CB_SMI_Mixto!F22/1000000)*J$25 -> 0 | K51: =(CB_SMI_Mixto!G22/1000000)*K$25 -> 0 | L51: =(CB_SMI_Mixto!H22/1000000)*L$25 -> 0 | M51: =(CB_SMI_Mixto!I22/1000000)*M$25 -> 0 | N51: =(CB_SMI_Mixto!J22/1000000)*N$25 -> 0 | ... U51: =(CB_SMI_Mixto!Q22/1000000)*U$25 -> 0 | W51: =NPV($D$67,G51:U51)+F51 -> 0 | X51: =PMT($D$67,15,-W51) -> 0 | Y51: =W51*1000000/7744865 -> 0 | Z51: =W51/$W$56 -> 0
C52: Reducción del consumo de Clientes Finales | F52: 0 | G52: =(CB_SMI_Mixto!C23/1000000)*G$25 -> 0 | H52: =(CB_SMI_Mixto!D23/1000000)*H$25 -> 0 | I52: =(CB_SMI_Mixto!E23/1000000)*I$25 -> 0 | J52: =(CB_SMI_Mixto!F23/1000000)*J$25 -> 0 | K52: =(CB_SMI_Mixto!G23/1000000)*K$25 -> 0 | L52: =(CB_SMI_Mixto!H23/1000000)*L$25 -> 0 | M52: =(CB_SMI_Mixto!I23/1000000)*M$25 -> 0 | N52: =(CB_SMI_Mixto!J23/1000000)*N$25 -> 0 | ... U52: =(CB_SMI_Mixto!Q23/1000000)*U$25 -> 0 | W52: =NPV($D$67,G52:U52)+F52 -> 0 | X52: =PMT($D$67,15,-W52) -> 0 | Y52: =W52*1000000/7744865 -> 0 | Z52: =W52/$W$56 -> 0
...

Sheet CB_SMI_Mixto_ALTA
A1: Concepto | B1: Periodo 0 | C1: Periodo 1 | D1: Periodo 2 | E1: Periodo 3 | F1: Periodo 4 | G1: Periodo 5 | H1: Periodo 6 | I1: Periodo 7 | J1: Periodo 8 | K1: Periodo 9 | L1: Periodo 10 | M1: Periodo 11 | N1: Periodo 12 | O1: Periodo 13 | P1: Periodo 14 | Q1: Periodo 15
A2: Energía facturada anual [MWh/año] | B2: 11914419 | C2: 12274234 | D2: 12644916 | E2: 13026793 | F2: 13420202 | G2: 13825492 | H2: 14243022 | I2: 14673161 | J2: 15116290 | K2: 15572802 | L2: 16043101 | M2: 16527603 | N2: 17026736 | O2: 17540944 | P2: 18070680 | Q2: 18616415
A3: Cantidad UM 1F | B3: 1231 | C3: 1 | D3: 1 | E3: 2 | F3: 2 | G3: 2 | H3: 2 | I3: 2 | J3: 2 | K3: 2 | L3: 2 | M3: 2 | N3: 2 | O3: 2 | P3: 2 | Q3: 2
A4: Cantidad UM 3F Directa | B4: 0 | C4: 0 | D4: 0 | E4: 0 | F4: 0 | G4: 0 | H4: 0 | I4: 0 | J4: 0 | K4: 0 | L4: 0 | M4: 0 | N4: 0 | O4: 0 | P4: 0 | Q4: 0
A5: Cantidad UM 3F Indirecta | B5: 42167 | C5: 147 | D5: 147 | E5: 148 | F5: 148 | G5: 148 | H5: 148 | I5: 150 | J5: 150 | K5: 150 | L5: 150 | M5: 150 | N5: 152 | O5: 152 | P5: 153 | Q5: 156
A6: Cantidad DCU | B6: 0 | C6: 0 | D6: 0 | E6: 0 | F6: 0 | G6: 0 | H6: 0 | I6: 0 | J6: 0 | K6: 0 | L6: 0 | M6: 0 | N6: 0 | O6: 0 | P6: 0 | Q6: 0
A7: Inversión UM 1F [USD/equipo] | B7: 129.408 | C7: 129.408 | D7: 129.408 | E7: 129.408 | F7: 129.408 | G7: 129.408 | H7: 129.408 | I7: 129.408 | J7: 129.408 | K7: 129.408 | L7: 129.408 | M7: 129.408 | N7: 129.408 | O7: 129.408 | P7: 129.408 | Q7: 129.408
A8: Inversión UM 3F Directa [USD/equipo] | B8: 0 | C8: 0 | D8: 0 | E8: 0 | F8: 0 | G8: 0 | H8: 0 | I8: 0 | J8: 0 | K8: 0 | L8: 0 | M8: 0 | N8: 0 | O8: 0 | P8: 0 | Q8: 0
A9: Inversión UM 3F Indirecta [USD/equipo] | B9: 717.592 | C9: 717.592 | D9: 717.592 | E9: 717.592 | F9: 717.592 | G9: 717.592 | H9: 717.592 | I9: 717.592 | J9: 717.592 | K9: 717.592 | L9: 717.592 | M9: 717.592 | N9: 717.592 | O9: 717.592 | P9: 717.592 | Q9: 717.592
A10: Inversión DCU [USD/equipo] | B10: 0 | C10: 0 | D10: 0 | E10: 0 | F10: 0 | G10: 0 | H10: 0 | I10: 0 | J10: 0 | K10: 0 | L10: 0 | M10: 0 | N10: 0 | O10: 0 | P10: 0 | Q10: 0
A11: Inversión SGO [USD] | B11: 796396.7 | C11: 2715.948 | D11: 2715.948 | E11: 2752.65 | F11: 2752.65 | G11: 2752.65 | H11: 2752.65 | I11: 2789.352 | J11: 2789.352 | K11: 2789.352 | L11: 2789.352 | M11: 2789.352 | N11: 2826.054 | O11: 2826.054 | P11: 2844.405 | Q11: 2899.458
A12: Inversión MDMS [USD] | B12: 59843.558 | C12: 204.08421 | D12: 204.08421 | E12: 206.84211 | F12: 206.84211 | G12: 206.84211 | H12: 206.84211 | I12: 209.6 | J12: 209.6 | K12: 209.6 | L12: 209.6 | M12: 209.6 | N12: 212.35789 | O12: 212.35789 | P12: 213.73684 | Q12: 217.87368
A13: Operación Comunicaciones [USD/año] | B13: 0 | C13: 0 | D13: 0 | E13: 0 | F13: 0 | G13: 0 | H13: 0 | I13: 0 | J13: 0 | K13: 0 | L13: 0 | M13: 0 | N13: 0 | O13: 0 | P13: 0 | Q13: 0
... A26: Ahorro por inversión evitada [USD/año] | B26: 1403357.3 | C26: 1404390.9 | D26: 1405453.2 | E26: 1420942.7 | F26: 1424275.1 | G26: 1426444.2 | H26: 1428005.8 | I26: 1429529.9 | J26: 1441345.7 | K26: 1444399 | L26: 1446816.9 | M26: 1449240.7 | N26: 1452114.7 | O26: 1456390.3 | P26: 1460678.6 | Q26: 1464979.4

Sheet Flujo SMI_Mixto_ALTA
B2: Escenario de implementación | G2: Supuestos y Consideraciones
B4: Densidad de clientes | D4: Tecnología | G4: Tasa de descuento | J4: 0.06 | K4: % | R4: Dólar | S4: 959.36 | T4: USD/$ | U4: 45946
B5: Alta | D5: Mixto_ALTA | G5: Vida útil del proyecto | J5: 15 | K5: años | R5: UF | S5: 39521.26 | T5: UF/$ | U5: 45946
B6: Media | D6: Mixto_ALTA | G6: Meta de despligue | J6: 3 | K6: años
B7: Baja | D7: Mixto_ALTA | G7: Objetivo de despligue UM 1F | J7: =(SUMIF($F$12:$U$12,"<="&$J$6,$F$17:$U$17)) / ($J$6) -> 411.66667 | K7: UM/año | L7: ="Razonable para chile en torno a 1M y 1,5M por año." -> Razonable para chile en torno a 1M y 1,5M por año.
B8: Muy Baja | D8: Mixto_ALTA | G8: Objetivo de despligue UM 3F Directa | J8: =(SUMIF($F$12:$U$12,"<="&$J$6,$F$18:$U$18)) / ($J$6) -> 0 | K8: UM/año | L8: ="Razonable para chile en torno a 1M y 1,5M por año." -> Razonable para chile en torno a 1M y 1,5M por año.
B9: Extremadamente Baja | D9: Mixto_ALTA | G9: Objetivo de despligue UM 3F Indirecta | J9: =(SUMIF($F$12:$U$12,"<="&$J$6,$F$19:$U$19)) / ($J$6) -> 14203 | K9: UM/año | L9: ="Razonable para chile en torno a 1M y 1,5M por año." -> Razonable para chile en torno a 1M y 1,5M por año.
B12: Despligue SMI Chile | E12: Periodo | F12: 0 | G12: 1 | H12: 2 | I12: 3 | J12: 4 | K12: 5 | L12: 6 | M12: 7 | N12: 8 | O12: 9 | P12: 10 | Q12: 11 | R12: 12 | S12: 13 | T12: 14 | U12: 15
E13: Año | F13: 2025 | G13: 2026 | H13: 2027 | I13: 2028 | J13: 2029 | K13: 2030 | L13: 2031 | M13: 2032 | N13: 2033 | O13: 2034 | P13: 2035 | Q13: 2036 | R13: 2037 | S13: 2038 | T13: 2039 | U13: 2040
B15: Datos de despliegue | C15: Energía Facturada anual [GWh] | F15: =CB_SMI_Mixto_ALTA!B2/1000 -> 11914.419 | G15: =CB_SMI_Mixto_ALTA!C2/1000 -> 12274.234 | H15: =CB_SMI_Mixto_ALTA!D2/1000 -> 12644.916 | I15: =CB_SMI_Mixto_ALTA!E2/1000 -> 13026.793 | J15: =CB_SMI_Mixto_ALTA!F2/1000 -> 13420.202 | K15: =CB_SMI_Mixto_ALTA!G2/1000 -> 13825.492 | L15: =CB_SMI_Mixto_ALTA!H2/1000 -> 14243.022 | M15: =CB_SMI_Mixto_ALTA!I2/1000 -> 14673.161 | ... U15: =CB_SMI_Mixto_ALTA!Q2/1000 -> 18616.415
C17: UM 1F [N° Equipos] | F17: =CB_SMI_Mixto_ALTA!B3 -> 1231 | G17: =CB_SMI_Mixto_ALTA!C3 -> 1 | H17: =CB_SMI_Mixto_ALTA!D3 -> 1 | I17: =CB_SMI_Mixto_ALTA!E3 -> 2 | J17: =CB_SMI_Mixto_ALTA!F3 -> 2 | K17: =CB_SMI_Mixto_ALTA!G3 -> 2 | L17: =CB_SMI_Mixto_ALTA!H3 -> 2 | M17: =CB_SMI_Mixto_ALTA!I3 -> 2 | ... U17: =CB_SMI_Mixto_ALTA!Q3 -> 2
C18: UM 3F Directa [N° Equipos] | F18: =CB_SMI_Mixto_ALTA!B4 -> 0 | G18: =CB_SMI_Mixto_ALTA!C4 -> 0 | H18: =CB_SMI_Mixto_ALTA!D4 -> 0 | I18: =CB_SMI_Mixto_ALTA!E4 -> 0 | J18: =CB_SMI_Mixto_ALTA!F4 -> 0 | K18: =CB_SMI_Mixto_ALTA!G4 -> 0 | L18: =CB_SMI_Mixto_ALTA!H4 -> 0 | M18: =CB_SMI_Mixto_ALTA!I4 -> 0 | ... U18: =CB_SMI_Mixto_ALTA!Q4 -> 0
C19: UM 3F Indirecta [N° Equipos] | F19: =CB_SMI_Mixto_ALTA!B5 -> 42167 | G19: =CB_SMI_Mixto_ALTA!C5 -> 147 | H19: =CB_SMI_Mixto_ALTA!D5 -> 147 | I19: =CB_SMI_Mixto_ALTA!E5 -> 148 | J19: =CB_SMI_Mixto_ALTA!F5 -> 148 | K19: =CB_SMI_Mixto_ALTA!G5 -> 148 | L19: =CB_SMI_Mixto_ALTA!H5 -> 148 | M19: =CB_SMI_Mixto_ALTA!I5 -> 150 | ... U19: =CB_SMI_Mixto_ALTA!Q5 -> 156
B21: Despliegue | C21: UM 1F instalados | F21: 0 | G21: =IF(G$12<=$J$6,$J7,G17) -> 411.66667 | H21: =IF(H$12<=$J$6,$J7,H17) -> 411.66667 | I21: =IF(I$12<=$J$6,$J7,I17) -> 411.66667 | J21: =IF(J$12<=$J$6,$J7,J17) -> 2 | K21: =IF(K$12<=$J$6,$J7,K17) -> 2 | L21: =IF(L$12<=$J$6,$J7,L17) -> 2 | M21: =IF(M$12<=$J$6,$J7,M17) -> 2 | N21: =IF(N$12<=$J$6,$J7,N17) -> 2 | ... U21: =IF(U$12<=$J$6,$J7,U17) -> 2
C22: UM 3F Directa instalados | F22: 0 | G22: =IF(G$12<=$J$6,$J8,G18) -> 0 | H22: =IF(H$12<=$J$6,$J8,H18) -> 0 | I22: =IF(I$12<=$J$6,$J8,I18) -> 0 | J22: =IF(J$12<=$J$6,$J8,J18) -> 0 | K22: =IF(K$12<=$J$6,$J8,K18) -> 0 | L22: =IF(L$12<=$J$6,$J8,L18) -> 0 | M22: =IF(M$12<=$J$6,$J8,M18) -> 0 | N22: =IF(N$12<=$J$6,$J8,N18) -> 0 | ... U22: =IF(U$12<=$J$6,$J8,U18) -> 0
C23: UM 3F Indirecta instalados | F23: 0 | G23: =IF(G$12<=$J$6,$J9,G19) -> 14203 | H23: =IF(H$12<=$J$6,$J9,H19) -> 14203 | I23: =IF(I$12<=$J$6,$J9,I19) -> 14203 | J23: =IF(J$12<=$J$6,$J9,J19) -> 148 | K23: =IF(K$12<=$J$6,$J9,K19) -> 148 | L23: =IF(L$12<=$J$6,$J9,L19) -> 148 | M23: =IF(M$12<=$J$6,$J9,M19) -> 150 | N23: =IF(N$12<=$J$6,$J9,N19) -> 150 | ... U23: =IF(U$12<=$J$6,$J9,U19) -> 156
C24: UM faltantes por instalar | F24: =SUM(F17:F19) -> 43398 | G24: =SUM(F24,G17:G19)-SUM(G21:G23) -> 28931.333 | H24: =SUM(G24,H17:H19)-SUM(H21:H23) -> 14464.667 | I24: =SUM(H24,I17:I19)-SUM(I21:I23) -> 0 | J24: =SUM(I24,J17:J19)-SUM(J21:J23) -> 0 | K24: =SUM(J24,K17:K19)-SUM(K21:K23) -> 0 | L24: =SUM(K24,L17:L19)-SUM(L21:L23) -> 0 | M24: =SUM(L24,M17:M19)-SUM(M21:M23) -> 0 | N24: =SUM(M24,N17:N19)-SUM(N21:N23) -> 0 | ... U24: =SUM(T24,U17:U19)-SUM(U21:U23) -> 0
C25: % de avance | F25: 0 | G25: =IF(G$12<=$J$6,SUM($F$21:G23)/SUM($F$17:G19),1) -> 0.33561445 | H25: =IF(H$12<=$J$6,SUM($F$21:H23)/SUM($F$17:H19),1) -> 0.66895531 | I25: =IF(I$12<=$J$6,SUM($F$21:I23)/SUM($F$17:I19),1) -> 1 | J25: =IF(J$12<=$J$6,SUM($F$21:J23)/SUM($F$17:J19),1) -> 1 | K25: =IF(K$12<=$J$6,SUM($F$21:K23)/SUM($F$17:K19),1) -> 1 | L25: =IF(L$12<=$J$6,SUM($F$21:L23)/SUM($F$17:L19),1) -> 1 | M25: =IF(M$12<=$J$6,SUM($F$21:M23)/SUM($F$17:M19),1) -> 1 | N25: =IF(N$12<=$J$6,SUM($F$21:N23)/SUM($F$17:N19),1) -> 1 | ... U25: =IF(U$12<=$J$6,SUM($F$21:U23)/SUM($F$17:U19),1) -> 1
B27: Flujo de caja [MUSD] | E27: Periodo | F27: 0 | G27: 1 | H27: 2 | I27: 3 | J27: 4 | K27: 5 | L27: 6 | M27: 7 | N27: 8 | O27: 9 | P27: 10 | Q27: 11 | R27: 12 | S27: 13 | T27: 14 | U27: 15
E28: Año | F28: 2025 | G28: 2026 | H28: 2027 | I28: 2028 | J28: 2029 | K28: 2030 | L28: 2031 | M28: 2032 | N28: 2033 | O28: 2034 | P28: 2035 | Q28: 2036 | R28: 2037 | S28: 2038 | T28: 2039 | U28: 2040 | W28: VAN [MUSD] | X28: AVAN [MUSD] | Y28: VAN [USD/# Clientes] | Z28: Participación %
B30: VI [MUSD] | C30: UM 1F | F30: 0 | G30: =((-CB_SMI_Mixto_ALTA!C7)*G21)/1000000 -> -0.05327296 | H30: =((-CB_SMI_Mixto_ALTA!D7)*H21)/1000000 -> -0.05327296 | I30: =((-CB_SMI_Mixto_ALTA!E7)*I21)/1000000 -> -0.05327296 | J30: =((-CB_SMI_Mixto_ALTA!F7)*J21)/1000000 -> -0.000258816 | K30: =((-CB_SMI_Mixto_ALTA!G7)*K21)/1000000 -> -0.000258816 | L30: =((-CB_SMI_Mixto_ALTA!H7)*L21)/1000000 -> -0.000258816 | M30: =((-CB_SMI_Mixto_ALTA!I7)*M21)/1000000 -> -0.000258816 | N30: =((-CB_SMI_Mixto_ALTA!J7)*N21)/1000000 -> -0.000258816 | ... U30: =((-CB_SMI_Mixto_ALTA!Q7)*U21)/1000000 -> -0.000258816 | W30: =NPV($D$67,G30:U30)+F30 -> -0.14422113 | X30: =PMT($D$67,15,-W30) -> -0.014849406 | Y30: =W30*1000000/7744865 -> -0.018621516 | Z30: =W30/$W$36 -> 0.0049677851
C31: UM 3F Directa | F31: 0 | G31: =((-CB_SMI_Mixto_ALTA!C8)*G22)/1000000 -> 0 | H31: =((-CB_SMI_Mixto_ALTA!D8)*H22)/1000000 -> 0 | I31: =((-CB_SMI_Mixto_ALTA!E8)*I22)/1000000 -> 0 | J31: =((-CB_SMI_Mixto_ALTA!F8)*J22)/1000000 -> 0 | K31: =((-CB_SMI_Mixto_ALTA!G8)*K22)/1000000 -> 0 | L31: =((-CB_SMI_Mixto_ALTA!H8)*L22)/1000000 -> 0 | M31: =((-CB_SMI_Mixto_ALTA!I8)*M22)/1000000 -> 0 | N31: =((-CB_SMI_Mixto_ALTA!J8)*N22)/1000000 -> 0 | ... U31: =((-CB_SMI_Mixto_ALTA!Q8)*U22)/1000000 -> 0 | W31: =NPV($D$67,G31:U31)+F31 -> 0 | X31: =PMT($D$67,15,-W31) -> 0 | Y31: =W31*1000000/7744865 -> 0 | Z31: =W31/$W$36 -> 0
C32: UM 3F Indirecta | F32: 0 | G32: =((-CB_SMI_Mixto_ALTA!C9)*G23)/1000000 -> -10.191959 | H32: =((-CB_SMI_Mixto_ALTA!D9)*H23)/1000000 -> -10.191959 | I32: =((-CB_SMI_Mixto_ALTA!E9)*I23)/1000000 -> -10.191959 | J32: =((-CB_SMI_Mixto_ALTA!F9)*J23)/1000000 -> -0.10620362 | K32: =((-CB_SMI_Mixto_ALTA!G9)*K23)/1000000 -> -0.10620362 | L32: =((-CB_SMI_Mixto_ALTA!H9)*L23)/1000000 -> -0.10620362 | M32: =((-CB_SMI_Mixto_ALTA!I9)*M23)/1000000 -> -0.1076388 | N32: =((-CB_SMI_Mixto_ALTA!J9)*N23)/1000000 -> -0.1076388 | ... U32: =((-CB_SMI_Mixto_ALTA!Q9)*U23)/1000000 -> -0.11194435 | W32: =NPV($D$67,G32:U32)+F32 -> -28.001838 | X32: =PMT($D$67,15,-W32) -> -2.8831466 | Y32: =W32*1000000/7744865 -> -3.6155359 | Z32: =W32/$W$36 -> 0.96454047
C33: DCU | F33: =((-CB_SMI_Mixto_ALTA!B10)*CB_SMI_Mixto_ALTA!B6)/1000000 -> 0 | G33: =((-CB_SMI_Mixto_ALTA!C10)*CB_SMI_Mixto_ALTA!C6)/1000000 -> 0 | H33: =((-CB_SMI_Mixto_ALTA!D10)*CB_SMI_Mixto_ALTA!D6)/1000000 -> 0 | I33: =((-CB_SMI_Mixto_ALTA!E10)*CB_SMI_Mixto_ALTA!E6)/1000000 -> 0 | J33: =((-CB_SMI_Mixto_ALTA!F10)*CB_SMI_Mixto_ALTA!F6)/1000000 -> 0 | K33: =((-CB_SMI_Mixto_ALTA!G10)*CB_SMI_Mixto_ALTA!G6)/1000000 -> 0 | L33: =((-CB_SMI_Mixto_ALTA!H10)*CB_SMI_Mixto_ALTA!H6)/1000000 -> 0 | M33: =((-CB_SMI_Mixto_ALTA!I10)*CB_SMI_Mixto_ALTA!I6)/1000000 -> 0 | ... U33: =((-CB_SMI_Mixto_ALTA!Q10)*CB_SMI_Mixto_ALTA!Q6)/1000000 -> 0 | W33: =NPV($D$67,G33:U33)+F33 -> 0 | X33: =PMT($D$67,15,-W33) -> 0 | Y33: =W33*1000000/7744865 -> 0 | Z33: =W33/$W$36 -> 0
C34: HES | F34: =(-CB_SMI_Mixto_ALTA!B11)/1000000 -> -0.7963967 | G34: =(-CB_SMI_Mixto_ALTA!C11)/1000000 -> -0.002715948 | H34: =(-CB_SMI_Mixto_ALTA!D11)/1000000 -> -0.002715948 | I34: =(-CB_SMI_Mixto_ALTA!E11)/1000000 -> -0.00275265 | J34: =(-CB_SMI_Mixto_ALTA!F11)/1000000 -> -0.00275265 | K34: =(-CB_SMI_Mixto_ALTA!G11)/1000000 -> -0.00275265 | L34: =(-CB_SMI_Mixto_ALTA!H11)/1000000 -> -0.00275265 | M34: =(-CB_SMI_Mixto_ALTA!I11)/1000000 -> -0.002789352 | ... U34: =(-CB_SMI_Mixto_ALTA!Q11)/1000000 -> -0.002899458 | W34: =NPV($D$67,G34:U34)+F34 -> -0.82334555 | X34: =PMT($D$67,15,-W34) -> -0.084773934 | Y34: =W34*1000000/7744865 -> -0.10630857 | Z34: =W34/$W$36 -> 0.028360643
C35: MDMS | F35: =(-CB_SMI_Mixto_ALTA!B12)/1000000 -> -0.059843558 | G35: =(-CB_SMI_Mixto_ALTA!C12)/1000000 -> -0.00020408421 | H35: =(-CB_SMI_Mixto_ALTA!D12)/1000000 -> -0.00020408421 | I35: =(-CB_SMI_Mixto_ALTA!E12)/1000000 -> -0.00020684211 | J35: =(-CB_SMI_Mixto_ALTA!F12)/1000000 -> -0.00020684211 | K35: =(-CB_SMI_Mixto_ALTA!G12)/1000000 -> -0.00020684211 | L35: =(-CB_SMI_Mixto_ALTA!H12)/1000000 -> -0.00020684211 | M35: =(-CB_SMI_Mixto_ALTA!I12)/1000000 -> -0.0002096 | ... U35: =(-CB_SMI_Mixto_ALTA!Q12)/1000000 -> -0.00021787368 | W35: =NPV($D$67,G35:U35)+F35 -> -0.061868573 | X35: =PMT($D$67,15,-W35) -> -0.0063701593 | Y35: =W35*1000000/7744865 -> -0.0079883346 | Z35: =W35/$W$36 -> 0.002131101
C36: VI Total: | F36: =SUM(F30:F35) -> -0.85624026 | G36: =SUM(G30:G35) -> -10.248152 | H36: =SUM(H30:H35) -> -10.248152 | I36: =SUM(I30:I35) -> -10.248192 | J36: =SUM(J30:J35) -> -0.10942192 | K36: =SUM(K30:K35) -> -0.10942192 | L36: =SUM(L30:L35) -> -0.10942192 | M36: =SUM(M30:M35) -> -0.11089657 | ... U36: =SUM(U30:U35) -> -0.1153205 | W36: =NPV($D$67,G36:U36)+F36 -> -29.031273 | X36: =PMT($D$67,15,-W36) -> -2.9891401 | Y36: =W36*1000000/7744865 -> -3.7484543 | Z36: =W36/$W$36 -> 1
B38: COMA [MUSD] | C38: Operación Comunicaciones UM - SGO | F38: 0 | G38: =(-CB_SMI_Mixto_ALTA!C13/1000000)*G$25 -> 0 | H38: =(-CB_SMI_Mixto_ALTA!D13/1000000)*H$25 -> 0 | I38: =(-CB_SMI_Mixto_ALTA!E13/1000000)*I$25 -> 0 | J38: =(-CB_SMI_Mixto_ALTA!F13/1000000)*J$25 -> 0 | K38: =(-CB_SMI_Mixto_ALTA!G13/1000000)*K$25 -> 0 | L38: =(-CB_SMI_Mixto_ALTA!H13/1000000)*L$25 -> 0 | M38: =(-CB_SMI_Mixto_ALTA!I13/1000000)*M$25 -> 0 | N38: =(-CB_SMI_Mixto_ALTA!J13/1000000)*N$25 -> 0 | ... U38: =(-CB_SMI_Mixto_ALTA!Q13/1000000)*U$25 -> 0 | W38: =NPV($D$67,G38:U38)+F38 -> 0 | X38: =PMT($D$67,15,-W38) -> 0 | Y38: =W38*1000000/7744865 -> 0 | Z38: =W38/$W$43 -> 0
C39: Operación Comunicaciones DCU - SGO | F39: 0 | G39: =(-CB_SMI_Mixto_ALTA!C14/1000000)*G$25 -> -0.24485517 | H39: =(-CB_SMI_Mixto_ALTA!D14/1000000)*H$25 -> -0.48805159 | I39: =(-CB_SMI_Mixto_ALTA!E14/1000000)*I$25 -> -0.72957278 | J39: =(-CB_SMI_Mixto_ALTA!F14/1000000)*J$25 -> -0.72957278 | K39: =(-CB_SMI_Mixto_ALTA!G14/1000000)*K$25 -> -0.72957278 | L39: =(-CB_SMI_Mixto_ALTA!H14/1000000)*L$25 -> -0.72957278 | M39: =(-CB_SMI_Mixto_ALTA!I14/1000000)*M$25 -> -0.72957278 | N39: =(-CB_SMI_Mixto_ALTA!J14/1000000)*N$25 -> -0.72957278 | ... U39: =(-CB_SMI_Mixto_ALTA!Q14/1000000)*U$25 -> -0.72957278 | W39: =NPV($D$67,G39:U39)+F39 -> -6.4135587 | X39: =PMT($D$67,15,-W39) -> -0.66035773 | Y39: =W39*1000000/7744865 -> -0.82810465 | Z39: =W39/$W$43 -> 0.6126196
C40: Operación HES | F40: 0 | G40: =(-CB_SMI_Mixto_ALTA!C15/1000000)*G$25 -> -0.11670284 | H40: =(-CB_SMI_Mixto_ALTA!D15/1000000)*H$25 -> -0.23340568 | I40: =(-CB_SMI_Mixto_ALTA!E15/1000000)*I$25 -> -0.35010853 | J40: =(-CB_SMI_Mixto_ALTA!F15/1000000)*J$25 -> -0.35130632 | K40: =(-CB_SMI_Mixto_ALTA!G15/1000000)*K$25 -> -0.35250412 | L40: =(-CB_SMI_Mixto_ALTA!H15/1000000)*L$25 -> -0.35370192 | M40: =(-CB_SMI_Mixto_ALTA!I15/1000000)*M$25 -> -0.35491569 | N40: =(-CB_SMI_Mixto_ALTA!J15/1000000)*N$25 -> -0.35612946 | ... U40: =(-CB_SMI_Mixto_ALTA!Q15/1000000)*U$25 -> -0.36472965 | W40: =NPV($D$67,G40:U40)+F40 -> -3.1257244 | X40: =PMT($D$67,15,-W40) -> -0.32183322 | Y40: =W40*1000000/7744865 -> -0.40358669 | Z40: =W40/$W$43 -> 0.29856748
C41: Operación MDMS | F41: 0 | G41: =(-CB_SMI_Mixto_ALTA!C16/1000000)*G$25 -> -0.016563417 | H41: =(-CB_SMI_Mixto_ALTA!D16/1000000)*H$25 -> -0.033126834 | I41: =(-CB_SMI_Mixto_ALTA!E16/1000000)*I$25 -> -0.049690251 | J41: =(-CB_SMI_Mixto_ALTA!F16/1000000)*J$25 -> -0.049860253 | K41: =(-CB_SMI_Mixto_ALTA!G16/1000000)*K$25 -> -0.050030254 | L41: =(-CB_SMI_Mixto_ALTA!H16/1000000)*L$25 -> -0.050200255 | M41: =(-CB_SMI_Mixto_ALTA!I16/1000000)*M$25 -> -0.050372523 | N41: =(-CB_SMI_Mixto_ALTA!J16/1000000)*N$25 -> -0.050544791 | ... U41: =(-CB_SMI_Mixto_ALTA!Q16/1000000)*U$25 -> -0.051765401 | W41: =NPV($D$67,G41:U41)+F41 -> -0.44362825 | X41: =PMT($D$67,15,-W41) -> -0.04567719 | Y41: =W41*1000000/7744865 -> -0.057280307 | Z41: =W41/$W$43 -> 0.042375126
C42: SyM Equipos | F42: 0 | G42: =(-CB_SMI_Mixto_ALTA!C17/1000000)*G$25 -> -0.018151416 | H42: =(-CB_SMI_Mixto_ALTA!D17/1000000)*H$25 -> -0.036302832 | I42: =(-CB_SMI_Mixto_ALTA!E17/1000000)*I$25 -> -0.054454248 | J42: =(-CB_SMI_Mixto_ALTA!F17/1000000)*J$25 -> -0.054640548 | K42: =(-CB_SMI_Mixto_ALTA!G17/1000000)*K$25 -> -0.054826848 | L42: =(-CB_SMI_Mixto_ALTA!H17/1000000)*L$25 -> -0.055013148 | M42: =(-CB_SMI_Mixto_ALTA!I17/1000000)*M$25 -> -0.055201932 | N42: =(-CB_SMI_Mixto_ALTA!J17/1000000)*N$25 -> -0.055390716 | ... U42: =(-CB_SMI_Mixto_ALTA!Q17/1000000)*U$25 -> -0.05672835 | W42: =NPV($D$67,G42:U42)+F42 -> -0.4861606 | X42: =PMT($D$67,15,-W42) -> -0.050056439 | Y42: =W42*1000000/7744865 -> -0.062771992 | Z42: =W42/$W$43 -> 0.046437793
C43: COMA Total: | F43: =SUM(F38:F42) -> 0 | G43: =SUM(G38:G42) -> -0.39627284 | H43: =SUM(H38:H42) -> -0.79088694 | I43: =SUM(I38:I42) -> -1.1838258 | J43: =SUM(J38:J42) -> -1.1853799 | K43: =SUM(K38:K42) -> -1.186934 | L43: =SUM(L38:L42) -> -1.1884881 | M43: =SUM(M38:M42) -> -1.1900629 | ... U43: =SUM(U38:U42) -> -1.2027962 | W43: =NPV($D$67,G43:U43)+F43 -> -10.469072 | X43: =PMT($D$67,15,-W43) -> -1.0779246 | Y43: =W43*1000000/7744865 -> -1.3517436 | Z43: =W43/$W$43 -> 1
B45: Costos Totales (VI + COMA) | F45: =F36+F43 -> -0.85624026 | G45: =G36+G43 -> -10.644425 | H45: =H36+H43 -> -11.039039 | I45: =I36+I43 -> -11.432017 | J45: =J36+J43 -> -1.2948018 | K45: =K36+K43 -> -1.2963559 | L45: =L36+L43 -> -1.29791 | M45: =M36+M43 -> -1.3009595 | ... U45: =U36+U43 -> -1.3181167 | W45: =NPV($D$67,G45:U45)+F45 -> -39.500345 | X45: =PMT($D$67,15,-W45) -> -4.0670647 | Y45: =W45*1000000/7744865 -> -5.100198
B47: Beneficios [MUSD] | C47: Ahorro de lectura pedestre | F47: 0 | G47: =(CB_SMI_Mixto_ALTA!C18/1000000)*G$25 -> 0 | H47: =(CB_SMI_Mixto_ALTA!D18/1000000)*H$25 -> 0 | I47: =(CB_SMI_Mixto_ALTA!E18/1000000)*I$25 -> 0 | J47: =(CB_SMI_Mixto_ALTA!F18/1000000)*J$25 -> 0 | K47: =(CB_SMI_Mixto_ALTA!G18/1000000)*K$25 -> 0 | L47: =(CB_SMI_Mixto_ALTA!H18/1000000)*L$25 -> 0 | M47: =(CB_SMI_Mixto_ALTA!I18/1000000)*M$25 -> 0 | N47: =(CB_SMI_Mixto_ALTA!J18/1000000)*N$25 -> 0 | ... U47: =(CB_SMI_Mixto_ALTA!Q18/1000000)*U$25 -> 0 | V47: =U47/$U$56 -> 0 | W47: =NPV($D$67,G47:U47)+F47 -> 0 | X47: =PMT($D$67,15,-W47) -> 0 | Y47: =W47*1000000/7744865 -> 0 | Z47: =W47/$W$56 -> 0
C48: Corte y Reposición remoto | F48: 0 | G48: =(CB_SMI_Mixto_ALTA!C19/1000000)*G$25 -> 0 | H48: =(CB_SMI_Mixto_ALTA!D19/1000000)*H$25 -> 0 | I48: =(CB_SMI_Mixto_ALTA!E19/1000000)*I$25 -> 0 | J48: =(CB_SMI_Mixto_ALTA!F19/1000000)*J$25 -> 0 | K48: =(CB_SMI_Mixto_ALTA!G19/1000000)*K$25 -> 0 | L48: =(CB_SMI_Mixto_ALTA!H19/1000000)*L$25 -> 0 | M48: =(CB_SMI_Mixto_ALTA!I19/1000000)*M$25 -> 0 | N48: =(CB_SMI_Mixto_ALTA!J19/1000000)*N$25 -> 0 | ... U48: =(CB_SMI_Mixto_ALTA!Q19/1000000)*U$25 -> 0 | V48: =U48/$U$56 -> 0 | W48: =NPV($D$67,G48:U48)+F48 -> 0 | X48: =PMT($D$67,15,-W48) -> 0 | Y48: =W48*1000000/7744865 -> 0 | Z48: =W48/$W$56 -> 0
C49: Reducción de Pérdidas No Técnicas | F49: 0 | G49: =(CB_SMI_Mixto_ALTA!C20/1000000)*G$25 -> 0 | H49: =(CB_SMI_Mixto_ALTA!D20/1000000)*H$25 -> 0 | I49: =(CB_SMI_Mixto_ALTA!E20/1000000)*I$25 -> 0 | J49: =(CB_SMI_Mixto_ALTA!F20/1000000)*J$25 -> 0 | K49: =(CB_SMI_Mixto_ALTA!G20/1000000)*K$25 -> 0 | L49: =(CB_SMI_Mixto_ALTA!H20/1000000)*L$25 -> 0 | M49: =(CB_SMI_Mixto_ALTA!I20/1000000)*M$25 -> 0 | N49: =(CB_SMI_Mixto_ALTA!J20/1000000)*N$25 -> 0 | ... U49: =(CB_SMI_Mixto_ALTA!Q20/1000000)*U$25 -> 0 | V49: =U49/$U$56 -> 0 | W49: =NPV($D$67,G49:U49)+F49 -> 0 | X49: =PMT($D$67,15,-W49) -> 0 | Y49: =W49*1000000/7744865 -> 0 | Z49: =W49/$W$56 -> 0
C50: Reducción del tiempo de respuesta ante Fallas | F50: 0 | G50: =(CB_SMI_Mixto_ALTA!C21/1000000)*G$25 -> 0.045996825 | H50: =(CB_SMI_Mixto_ALTA!D21/1000000)*H$25 -> 0.09168205 | I50: =(CB_SMI_Mixto_ALTA!E21/1000000)*I$25 -> 0.13705258 | J50: =(CB_SMI_Mixto_ALTA!F21/1000000)*J$25 -> 0.13705258 | K50: =(CB_SMI_Mixto_ALTA!G21/1000000)*K$25 -> 0.13705258 | L50: =(CB_SMI_Mixto_ALTA!H21/1000000)*L$25 -> 0.13705258 | M50: =(CB_SMI_Mixto_ALTA!I21/1000000)*M$25 -> 0.13705258 | N50: =(CB_SMI_Mixto_ALTA!J21/1000000)*N$25 -> 0.13705258 | ... U50: =(CB_SMI_Mixto_ALTA!Q21/1000000)*U$25 -> 0.13705258 | V50: =U50/$U$56 -> 0.085549216 | W50: =NPV($D$67,G50:U50)+F50 -> 1.2048075 | X50: =PMT($D$67,15,-W50) -> 0.12405031 | Y50: =W50*1000000/7744865 -> 0.1555621 | Z50: =W50/$W$56 -> 0.087158561
C51: Reducción del costo de la energía en horas de Sol | F51: 0 | G51: =(CB_SMI_Mixto_ALTA!C22/1000000)*G$25 -> 0 | H51: =(CB_SMI_Mixto_ALTA!D22/1000000)*H$25 -> 0 | I51: =(CB_SMI_Mixto_ALTA!E22/1000000)*I$25 -> 0 | J51: =(CB_SMI_Mixto_ALTA!F22/1000000)*J$25 -> 0 | K51: =(CB_SMI_Mixto_ALTA!G22/1000000)*K$25 -> 0 | L51: =(CB_SMI_Mixto_ALTA!H22/1000000)*L$25 -> 0 | M51: =(CB_SMI_Mixto_ALTA!I22/1000000)*M$25 -> 0 | N51: =(CB_SMI_Mixto_ALTA!J22/1000000)*N$25 -> 0 | ... U51: =(CB_SMI_Mixto_ALTA!Q22/1000000)*U$25 -> 0 | V51: =U51/$U$56 -> 0 | W51: =NPV($D$67,G51:U51)+F51 -> 0 | X51: =PMT($D$67,15,-W51) -> 0 | Y51: =W51*1000000/7744865 -> 0 | Z51: =W51/$W$56 -> 0
C52: Reducción del consumo de Clientes Finales | F52: 0 | G52: =(CB_SMI_Mixto_ALTA!C23/1000000)*G$25 -> 0 | H52: =(CB_SMI_Mixto_ALTA!D23/1000000)*H$25 -> 0 | I52: =(CB_SMI_Mixto_ALTA!E23/1000000)*I$25 -> 0 | J52: =(CB_SMI_Mixto_ALTA!F23/1000000)*J$25 -> 0 | K52: =(CB_SMI_Mixto_ALTA!G23/1000000)*K$25 -> 0 | L52: =(CB_SMI_Mixto_ALTA!H23/1000000)*L$25 -> 0 | M52: =(CB_SMI_Mixto_ALTA!I23/1000000)*M$25 -> 0 | N52: =(CB_SMI_Mixto_ALTA!J23/1000000)*N$25 -> 0 | ... U52: =(CB_SMI_Mixto_ALTA!Q23/1000000)*U$25 -> 0 | V52: =U52/$U$56 -> 0 | W52: =NPV($D$67,G52:U52)+F52 -> 0 | X52: =PMT($D$67,15,-W52) -> 0 | Y52: =W52*1000000/7744865 -> 0 | Z52: =W52/$W$56 -> 0
...

Sheet CB_SMI_Mixto_MEDIA
A1: Concepto | B1: Periodo 0 | C1: Periodo 1 | D1: Periodo 2 | E1: Periodo 3 | F1: Periodo 4 | G1: Periodo 5 | H1: Periodo 6 | I1: Periodo 7 | J1: Periodo 8 | K1: Periodo 9 | L1: Periodo 10 | M1: Periodo 11 | N1: Periodo 12 | O1: Periodo 13 | P1: Periodo 14 | Q1: Periodo 15
A2: Energía facturada anual [MWh/año] | B2: 8711682.8 | C2: 8974775.6 | D2: 9245813.9 | E2: 9525037.4 | F2: 9812693.6 | G2: 10109037 | H2: 10414330 | I2: 10728843 | J2: 11052854 | K2: 11386650 | L2: 11730527 | M2: 12084789 | N2: 12449749 | O2: 12825732 | P2: 13213069 | Q2: 13612103
A3: Cantidad UM 1F | B3: 2896 | C3: 11 | D3: 11 | E3: 11 | F3: 11 | G3: 13 | H3: 13 | I3: 13 | J3: 13 | K3: 13 | L3: 13 | M3: 13 | N3: 13 | O3: 13 | P3: 13 | Q3: 13
A4: Cantidad UM 3F Directa | B4: 0 | C4: 0 | D4: 0 | E4: 0 | F4: 0 | G4: 0 | H4: 0 | I4: 0 | J4: 0 | K4: 0 | L4: 0 | M4: 0 | N4: 0 | O4: 0 | P4: 0 | Q4: 0
A5: Cantidad UM 3F Indirecta | B5: 46463 | C5: 232 | D5: 232 | E5: 235 | F5: 235 | G5: 237 | H5: 237 | I5: 237 | J5: 239 | K5: 239 | L5: 239 | M5: 241 | N5: 241 | O5: 244 | P5: 247 | Q5: 250
A6: Cantidad DCU | B6: 0 | C6: 0 | D6: 0 | E6: 0 | F6: 0 | G6: 0 | H6: 0 | I6: 0 | J6: 0 | K6: 0 | L6: 0 | M6: 0 | N6: 0 | O6: 0 | P6: 0 | Q6: 0
A7: Inversión UM 1F [USD/equipo] | B7: 138.76 | C7: 138.76 | D7: 138.76 | E7: 138.76 | F7: 138.76 | G7: 138.76 | H7: 138.76 | I7: 138.76 | J7: 138.76 | K7: 138.76 | L7: 138.76 | M7: 138.76 | N7: 138.76 | O7: 138.76 | P7: 138.76 | Q7: 138.76
A8: Inversión UM 3F Directa [USD/equipo] | B8: 0 | C8: 0 | D8: 0 | E8: 0 | F8: 0 | G8: 0 | H8: 0 | I8: 0 | J8: 0 | K8: 0 | L8: 0 | M8: 0 | N8: 0 | O8: 0 | P8: 0 | Q8: 0
A9: Inversión UM 3F Indirecta [USD/equipo] | B9: 717.592 | C9: 717.592 | D9: 717.592 | E9: 717.592 | F9: 717.592 | G9: 717.592 | H9: 717.592 | I9: 717.592 | J9: 717.592 | K9: 717.592 | L9: 717.592 | M9: 717.592 | N9: 717.592 | O9: 717.592 | P9: 717.592 | Q9: 717.592
A10: Inversión DCU [USD/equipo] | B10: 0 | C10: 0 | D10: 0 | E10: 0 | F10: 0 | G10: 0 | H10: 0 | I10: 0 | J10: 0 | K10: 0 | L10: 0 | M10: 0 | N10: 0 | O10: 0 | P10: 0 | Q10: 0
A11: Inversión SGO [USD] | B11: 905787.01 | C11: 4459.293 | D11: 4459.293 | E11: 4514.346 | F11: 4514.346 | G11: 4587.75 | H11: 4587.75 | I11: 4587.75 | J11: 4624.452 | K11: 4624.452 | L11: 4624.452 | M11: 4661.154 | N11: 4661.154 | O11: 4716.207 | P11: 4771.26 | Q11: 4826.313
A12: Inversión MDMS [USD] | B12: 68063.463 | C12: 335.08421 | D12: 335.08421 | E12: 339.22105 | F12: 339.22105 | G12: 344.73684 | H12: 344.73684 | I12: 344.73684 | J12: 347.49474 | K12: 347.49474 | L12: 347.49474 | M12: 350.25263 | N12: 350.25263 | O12: 354.38947 | P12: 358.52632 | Q12: 362.66316
A13: Operación Comunicaciones [USD/año] | B13: 0 | C13: 0 | D13: 0 | E13: 0 | F13: 0 | G13: 0 | H13: 0 | I13: 0 | J13: 0 | K13: 0 | L13: 0 | M13: 0 | N13: 0 | O13: 0 | P13: 0 | Q13: 0
... A26: Ahorro por inversión evitada [USD/año] | B26: 1901322.8 | C26: 1902723.1 | D26: 1904162.4 | E26: 1925148.1 | F26: 1929663.1 | G26: 1932601.8 | H26: 1934717.6 | I26: 1936782.4 | J26: 1952790.9 | K26: 1956927.7 | L26: 1960203.6 | M26: 1963487.4 | N26: 1967381.3 | O26: 1973174 | P26: 1978983.8 | Q26: 1984810.8

Sheet Flujo SMI_Mixto_MEDIA
B2: Escenario de implementación | G2: Supuestos y Consideraciones
B4: Densidad de clientes | D4: Tecnología | G4: Tasa de descuento | J4: 0.06 | K4: % | R4: Dólar | S4: 959.36 | T4: USD/$ | U4: 45946
B5: Alta | D5: Mixto_MEDIA | G5: Vida útil del proyecto | J5: 15 | K5: años | R5: UF | S5: 39521.26 | T5: UF/$ | U5: 45946
B6: Media | D6: Mixto_MEDIA | G6: Meta de despligue | J6: 3 | K6: años
B7: Baja | D7: Mixto_MEDIA | G7: Objetivo de despligue UM 1F | J7: =(SUMIF($F$12:$U$12,"<="&$J$6,$F$17:$U$17)) / ($J$6) -> 976.33333 | K7: UM/año | L7: ="Razonable para chile en torno a 1M y 1,5M por año." -> Razonable para chile en torno a 1M y 1,5M por año.
B8: Muy Baja | D8: Mixto_MEDIA | G8: Objetivo de despligue UM 3F Directa | J8: =(SUMIF($F$12:$U$12,"<="&$J$6,$F$18:$U$18)) / ($J$6) -> 0 | K8: UM/año | L8: ="Razonable para chile en torno a 1M y 1,5M por año." -> Razonable para chile en torno a 1M y 1,5M por año.
B9: Extremadamente Baja | D9: Mixto_MEDIA | G9: Objetivo de despligue UM 3F Indirecta | J9: =(SUMIF($F$12:$U$12,"<="&$J$6,$F$19:$U$19)) / ($J$6) -> 15720.667 | K9: UM/año | L9: ="Razonable para chile en torno a 1M y 1,5M por año." -> Razonable para chile en torno a 1M y 1,5M por año.
B12: Despligue SMI Chile | E12: Periodo | F12: 0 | G12: 1 | H12: 2 | I12: 3 | J12: 4 | K12: 5 | L12: 6 | M12: 7 | N12: 8 | O12: 9 | P12: 10 | Q12: 11 | R12: 12 | S12: 13 | T12: 14 | U12: 15
E13: Año | F13: 2025 | G13: 2026 | H13: 2027 | I13: 2028 | J13: 2029 | K13: 2030 | L13: 2031 | M13: 2032 | N13: 2033 | O13: 2034 | P13: 2035 | Q13: 2036 | R13: 2037 | S13: 2038 | T13: 2039 | U13: 2040
B15: Datos de despliegue | C15: Energía Facturada anual [GWh] | F15: =CB_SMI_Mixto_MEDIA!B2/1000 -> 8711.6828 | G15: =CB_SMI_Mixto_MEDIA!C2/1000 -> 8974.7756 | H15: =CB_SMI_Mixto_MEDIA!D2/1000 -> 9245.8139 | I15: =CB_SMI_Mixto_MEDIA!E2/1000 -> 9525.0374 | J15: =CB_SMI_Mixto_MEDIA!F2/1000 -> 9812.6936 | K15: =CB_SMI_Mixto_MEDIA!G2/1000 -> 10109.037 | L15: =CB_SMI_Mixto_MEDIA!H2/1000 -> 10414.33 | M15: =CB_SMI_Mixto_MEDIA!I2/1000 -> 10728.843 | ... U15: =CB_SMI_Mixto_MEDIA!Q2/1000 -> 13612.103
C17: UM 1F [N° Equipos] | F17: =CB_SMI_Mixto_MEDIA!B3 -> 2896 | G17: =CB_SMI_Mixto_MEDIA!C3 -> 11 | H17: =CB_SMI_Mixto_MEDIA!D3 -> 11 | I17: =CB_SMI_Mixto_MEDIA!E3 -> 11 | J17: =CB_SMI_Mixto_MEDIA!F3 -> 11 | K17: =CB_SMI_Mixto_MEDIA!G3 -> 13 | L17: =CB_SMI_Mixto_MEDIA!H3 -> 13 | M17: =CB_SMI_Mixto_MEDIA!I3 -> 13 | ... U17: =CB_SMI_Mixto_MEDIA!Q3 -> 13
C18: UM 3F Directa [N° Equipos] | F18: =CB_SMI_Mixto_MEDIA!B4 -> 0 | G18: =CB_SMI_Mixto_MEDIA!C4 -> 0 | H18: =CB_SMI_Mixto_MEDIA!D4 -> 0 | I18: =CB_SMI_Mixto_MEDIA!E4 -> 0 | J18: =CB_SMI_Mixto_MEDIA!F4 -> 0 | K18: =CB_SMI_Mixto_MEDIA!G4 -> 0 | L18: =CB_SMI_Mixto_MEDIA!H4 -> 0 | M18: =CB_SMI_Mixto_MEDIA!I4 -> 0 | ... U18: =CB_SMI_Mixto_MEDIA!Q4 -> 0
C19: UM 3F Indirecta [N° Equipos] | F19: =CB_SMI_Mixto_MEDIA!B5 -> 46463 | G19: =CB_SMI_Mixto_MEDIA!C5 -> 232 | H19: =CB_SMI_Mixto_MEDIA!D5 -> 232 | I19: =CB_SMI_Mixto_MEDIA!E5 -> 235 | J19: =CB_SMI_Mixto_MEDIA!F5 -> 235 | K19: =CB_SMI_Mixto_MEDIA!G5 -> 237 | L19: =CB_SMI_Mixto_MEDIA!H5 -> 237 | M19: =CB_SMI_Mixto_MEDIA!I5 -> 237 | ... U19: =CB_SMI_Mixto_MEDIA!Q5 -> 250
B21: Despliegue | C21: UM 1F instalados | F21: 0 | G21: =IF(G$12<=$J$6,$J7,G17) -> 976.33333 | H21: =IF(H$12<=$J$6,$J7,H17) -> 976.33333 | I21: =IF(I$12<=$J$6,$J7,I17) -> 976.33333 | J21: =IF(J$12<=$J$6,$J7,J17) -> 11 | K21: =IF(K$12<=$J$6,$J7,K17) -> 13 | L21: =IF(L$12<=$J$6,$J7,L17) -> 13 | M21: =IF(M$12<=$J$6,$J7,M17) -> 13 | N21: =IF(N$12<=$J$6,$J7,N17) -> 13 | ... U21: =IF(U$12<=$J$6,$J7,U17) -> 13
C22: UM 3F Directa instalados | F22: 0 | G22: =IF(G$12<=$J$6,$J8,G18) -> 0 | H22: =IF(H$12<=$J$6,$J8,H18) -> 0 | I22: =IF(I$12<=$J$6,$J8,I18) -> 0 | J22: =IF(J$12<=$J$6,$J8,J18) -> 0 | K22: =IF(K$12<=$J$6,$J8,K18) -> 0 | L22: =IF(L$12<=$J$6,$J8,L18) -> 0 | M22: =IF(M$12<=$J$6,$J8,M18) -> 0 | N22: =IF(N$12<=$J$6,$J8,N18) -> 0 | ... U22: =IF(U$12<=$J$6,$J8,U18) -> 0
C23: UM 3F Indirecta instalados | F23: 0 | G23: =IF(G$12<=$J$6,$J9,G19) -> 15720.667 | H23: =IF(H$12<=$J$6,$J9,H19) -> 15720.667 | I23: =IF(I$12<=$J$6,$J9,I19) -> 15720.667 | J23: =IF(J$12<=$J$6,$J9,J19) -> 235 | K23: =IF(K$12<=$J$6,$J9,K19) -> 237 | L23: =IF(L$12<=$J$6,$J9,L19) -> 237 | M23: =IF(M$12<=$J$6,$J9,M19) -> 237 | N23: =IF(N$12<=$J$6,$J9,N19) -> 239 | ... U23: =IF(U$12<=$J$6,$J9,U19) -> 250
C24: UM faltantes por instalar | F24: =SUM(F17:F19) -> 49359 | G24: =SUM(F24,G17:G19)-SUM(G21:G23) -> 32905 | H24: =SUM(G24,H17:H19)-SUM(H21:H23) -> 16451 | I24: =SUM(H24,I17:I19)-SUM(I21:I23) -> 0 | J24: =SUM(I24,J17:J19)-SUM(J21:J23) -> 0 | K24: =SUM(J24,K17:K19)-SUM(K21:K23) -> 0 | L24: =SUM(K24,L17:L19)-SUM(L21:L23) -> 0 | M24: =SUM(L24,M17:M19)-SUM(M21:M23) -> 0 | N24: =SUM(M24,N17:N19)-SUM(N21:N23) -> 0 | ... U24: =SUM(T24,U17:U19)-SUM(U21:U23) -> 0
C25: % de avance | F25: 0 | G25: =IF(G$12<=$J$6,SUM($F$21:G23)/SUM($F$17:G19),1) -> 0.33661949 | H25: =IF(H$12<=$J$6,SUM($F$21:H23)/SUM($F$17:H19),1) -> 0.66995687 | I25: =IF(I$12<=$J$6,SUM($F$21:I23)/SUM($F$17:I19),1) -> 1 | J25: =IF(J$12<=$J$6,SUM($F$21:J23)/SUM($F$17:J19),1) -> 1 | K25: =IF(K$12<=$J$6,SUM($F$21:K23)/SUM($F$17:K19),1) -> 1 | L25: =IF(L$12<=$J$6,SUM($F$21:L23)/SUM($F$17:L19),1) -> 1 | M25: =IF(M$12<=$J$6,SUM($F$21:M23)/SUM($F$17:M19),1) -> 1 | N25: =IF(N$12<=$J$6,SUM($F$21:N23)/SUM($F$17:N19),1) -> 1 | ... U25: =IF(U$12<=$J$6,SUM($F$21:U23)/SUM($F$17:U19),1) -> 1
B27: Flujo de caja [MUSD] | E27: Periodo | F27: 0 | G27: 1 | H27: 2 | I27: 3 | J27: 4 | K27: 5 | L27: 6 | M27: 7 | N27: 8 | O27: 9 | P27: 10 | Q27: 11 | R27: 12 | S27: 13 | T27: 14 | U27: 15
E28: Año | F28: 2025 | G28: 2026 | H28: 2027 | I28: 2028 | J28: 2029 | K28: 2030 | L28: 2031 | M28: 2032 | N28: 2033 | O28: 2034 | P28: 2035 | Q28: 2036 | R28: 2037 | S28: 2038 | T28: 2039 | U28: 2040 | W28: VAN [MUSD] | X28: AVAN [MUSD] | Y28: VAN [USD/# Clientes] | Z28: Participación %
B30: VI [MUSD] | C30: UM 1F | F30: 0 | G30: =((-CB_SMI_Mixto_MEDIA!C7)*G21)/1000000 -> -0.13547601 | H30: =((-CB_SMI_Mixto_MEDIA!D7)*H21)/1000000 -> -0.13547601 | I30: =((-CB_SMI_Mixto_MEDIA!E7)*I21)/1000000 -> -0.13547601 | J30: =((-CB_SMI_Mixto_MEDIA!F7)*J21)/1000000 -> -0.00152636 | K30: =((-CB_SMI_Mixto_MEDIA!G7)*K21)/1000000 -> -0.00180388 | L30: =((-CB_SMI_Mixto_MEDIA!H7)*L21)/1000000 -> -0.00180388 | M30: =((-CB_SMI_Mixto_MEDIA!I7)*M21)/1000000 -> -0.00180388 | N30: =((-CB_SMI_Mixto_MEDIA!J7)*N21)/1000000 -> -0.00180388 | ... U30: =((-CB_SMI_Mixto_MEDIA!Q7)*U21)/1000000 -> -0.00180388 | W30: =NPV($D$67,G30:U30)+F30 -> -0.37460712 | X30: =PMT($D$67,15,-W30) -> -0.038570584 | Y30: =W30*1000000/7744865 -> -0.048368451 | Z30: =W30/$W$36 -> 0.011434322
C31: UM 3F Directa | F31: 0 | G31: =((-CB_SMI_Mixto_MEDIA!C8)*G22)/1000000 -> 0 | H31: =((-CB_SMI_Mixto_MEDIA!D8)*H22)/1000000 -> 0 | I31: =((-CB_SMI_Mixto_MEDIA!E8)*I22)/1000000 -> 0 | J31: =((-CB_SMI_Mixto_MEDIA!F8)*J22)/1000000 -> 0 | K31: =((-CB_SMI_Mixto_MEDIA!G8)*K22)/1000000 -> 0 | L31: =((-CB_SMI_Mixto_MEDIA!H8)*L22)/1000000 -> 0 | M31: =((-CB_SMI_Mixto_MEDIA!I8)*M22)/1000000 -> 0 | N31: =((-CB_SMI_Mixto_MEDIA!J8)*N22)/1000000 -> 0 | ... U31: =((-CB_SMI_Mixto_MEDIA!Q8)*U22)/1000000 -> 0 | W31: =NPV($D$67,G31:U31)+F31 -> 0 | X31: =PMT($D$67,15,-W31) -> 0 | Y31: =W31*1000000/7744865 -> 0 | Z31: =W31/$W$36 -> 0
C32: UM 3F Indirecta | F32: 0 | G32: =((-CB_SMI_Mixto_MEDIA!C9)*G23)/1000000 -> -11.281025 | H32: =((-CB_SMI_Mixto_MEDIA!D9)*H23)/1000000 -> -11.281025 | I32: =((-CB_SMI_Mixto_MEDIA!E9)*I23)/1000000 -> -11.281025 | J32: =((-CB_SMI_Mixto_MEDIA!F9)*J23)/1000000 -> -0.16863412 | K32: =((-CB_SMI_Mixto_MEDIA!G9)*K23)/1000000 -> -0.1700693 | L32: =((-CB_SMI_Mixto_MEDIA!H9)*L23)/1000000 -> -0.1700693 | M32: =((-CB_SMI_Mixto_MEDIA!I9)*M23)/1000000 -> -0.1700693 | N32: =((-CB_SMI_Mixto_MEDIA!J9)*N23)/1000000 -> -0.17150449 | ... U32: =((-CB_SMI_Mixto_MEDIA!Q9)*U23)/1000000 -> -0.179398 | W32: =NPV($D$67,G32:U32)+F32 -> -31.365246 | X32: =PMT($D$67,15,-W32) -> -3.2294525 | Y32: =W32*1000000/7744865 -> -4.0498119 | Z32: =W32/$W$36 -> 0.95737725
C33: DCU | F33: =((-CB_SMI_Mixto_MEDIA!B10)*CB_SMI_Mixto_MEDIA!B6)/1000000 -> 0 | G33: =((-CB_SMI_Mixto_MEDIA!C10)*CB_SMI_Mixto_MEDIA!C6)/1000000 -> 0 | H33: =((-CB_SMI_Mixto_MEDIA!D10)*CB_SMI_Mixto_MEDIA!D6)/1000000 -> 0 | I33: =((-CB_SMI_Mixto_MEDIA!E10)*CB_SMI_Mixto_MEDIA!E6)/1000000 -> 0 | J33: =((-CB_SMI_Mixto_MEDIA!F10)*CB_SMI_Mixto_MEDIA!F6)/1000000 -> 0 | K33: =((-CB_SMI_Mixto_MEDIA!G10)*CB_SMI_Mixto_MEDIA!G6)/1000000 -> 0 | L33: =((-CB_SMI_Mixto_MEDIA!H10)*CB_SMI_Mixto_MEDIA!H6)/1000000 -> 0 | M33: =((-CB_SMI_Mixto_MEDIA!I10)*CB_SMI_Mixto_MEDIA!I6)/1000000 -> 0 | ... U33: =((-CB_SMI_Mixto_MEDIA!Q10)*CB_SMI_Mixto_MEDIA!Q6)/1000000 -> 0 | W33: =NPV($D$67,G33:U33)+F33 -> 0 | X33: =PMT($D$67,15,-W33) -> 0 | Y33: =W33*1000000/7744865 -> 0 | Z33: =W33/$W$36 -> 0
C34: HES | F34: =(-CB_SMI_Mixto_MEDIA!B11)/1000000 -> -0.90578701 | G34: =(-CB_SMI_Mixto_MEDIA!C11)/1000000 -> -0.004459293 | H34: =(-CB_SMI_Mixto_MEDIA!D11)/1000000 -> -0.004459293 | I34: =(-CB_SMI_Mixto_MEDIA!E11)/1000000 -> -0.004514346 | J34: =(-CB_SMI_Mixto_MEDIA!F11)/1000000 -> -0.004514346 | K34: =(-CB_SMI_Mixto_MEDIA!G11)/1000000 -> -0.00458775 | L34: =(-CB_SMI_Mixto_MEDIA!H11)/1000000 -> -0.00458775 | M34: =(-CB_SMI_Mixto_MEDIA!I11)/1000000 -> -0.00458775 | ... U34: =(-CB_SMI_Mixto_MEDIA!Q11)/1000000 -> -0.004826313 | W34: =NPV($D$67,G34:U34)+F34 -> -0.95037042 | X34: =PMT($D$67,15,-W34) -> -0.097852765 | Y34: =W34*1000000/7744865 -> -0.12270975 | Z34: =W34/$W$36 -> 0.029008636
C35: MDMS | F35: =(-CB_SMI_Mixto_MEDIA!B12)/1000000 -> -0.068063463 | G35: =(-CB_SMI_Mixto_MEDIA!C12)/1000000 -> -0.00033508421 | H35: =(-CB_SMI_Mixto_MEDIA!D12)/1000000 -> -0.00033508421 | I35: =(-CB_SMI_Mixto_MEDIA!E12)/1000000 -> -0.00033922105 | J35: =(-CB_SMI_Mixto_MEDIA!F12)/1000000 -> -0.00033922105 | K35: =(-CB_SMI_Mixto_MEDIA!G12)/1000000 -> -0.00034473684 | L35: =(-CB_SMI_Mixto_MEDIA!H12)/1000000 -> -0.00034473684 | M35: =(-CB_SMI_Mixto_MEDIA!I12)/1000000 -> -0.00034473684 | ... U35: =(-CB_SMI_Mixto_MEDIA!Q12)/1000000 -> -0.00036266316 | W35: =NPV($D$67,G35:U35)+F35 -> -0.07141359 | X35: =PMT($D$67,15,-W35) -> -0.0073529406 | Y35: =W35*1000000/7744865 -> -0.0092207663 | Z35: =W35/$W$36 -> 0.0021797931
C36: VI Total: | F36: =SUM(F30:F35) -> -0.97385047 | G36: =SUM(G30:G35) -> -11.421295 | H36: =SUM(H30:H35) -> -11.421295 | I36: =SUM(I30:I35) -> -11.421354 | J36: =SUM(J30:J35) -> -0.17501405 | K36: =SUM(K30:K35) -> -0.17680567 | L36: =SUM(L30:L35) -> -0.17680567 | M36: =SUM(M30:M35) -> -0.17680567 | ... U36: =SUM(U30:U35) -> -0.18639086 | W36: =NPV($D$67,G36:U36)+F36 -> -32.761638 | X36: =PMT($D$67,15,-W36) -> -3.3732288 | Y36: =W36*1000000/7744865 -> -4.2301109 | Z36: =W36/$W$36 -> 1
